Workbook

Sheet README
A1: Manual-calculation check of the brick-masonry delay-risk tool
A3: What this is | B3: Hand calculations, written as live Excel formulas, for the ILLUSTRATIVE example case (examples/example_analysis_case.json). Each tool value is the number printed by the tool in the validation run of 9 Oct 2026; the workbook recomputes the same quantity by hand and shows the difference.
A4: Not evidence | B4: Every probability, delay range, duration and cost in this example is an Assumption placeholder, not site data. This workbook shows the arithmetic is right, not that the numbers describe a real site.
A5: Colour legend | B5: Blue text on yellow = input you may change. Black = formula. Green = link to another sheet. Tool values (pasted from the validation run) are blue text on white.
A6: Sheets | B6: Inputs: case numbers. Risk_Calc: PERT mean, variance, EMV, totals. Matrix: 5x5 class and level by hand. Mitigation_Calc: net benefit and break-even. Options: 23 options, exact total expected cost vs tool. Copula: occurrence-correlation check. All_Checks: all 242 checks of the run. Test_Summary: counts and findings.
A7: Exact values | B7: Option costs on the Options sheet and the copula joint probabilities come from numerical convolution and a bivariate-normal integral (scripts in report/scripts/validation_2026-10-09/). They cannot be written as a cell formula, so they are pasted as values; every sum, rank and difference around them is a formula.
A8: Changing inputs | B8: If you change a blue input on Inputs, the hand columns recompute but the pasted tool columns do not, so differences will appear. Re-run the tool and paste new tool values to compare again.
A9: Source | B9: Case: examples/example_analysis_case.json. Tool and exact values: report/scripts/validation_2026-10-09/v1_results.json (run of 9 Oct 2026, seed 12345, n = 10,000 and 200,000). Formulas: Beta-PERT mean (a + lambda*m + b)/(lambda + 2) and variance (mean - a)(b - mean)/(lambda + 3); event EMV = p x mean delay x delay cost per day.

Sheet Inputs
A1: Inputs (ILLUSTRATIVE example case; all values are Assumptions)
A3: Quantity | B3: Value | C3: Unit | D3: Note
A4: Planned duration T0 | B4: 16 | C4: days | D4: activity.planned_duration_days
A5: Deadline | B5: 20 | C5: days | D5: activity.deadline_days
A6: Delay cost Cd | B6: 8000 | C6: INR/day | D6: cost.cost_per_delay_day
A7: Liquidated damages LD | B7: 5000 | C7: INR/day | D7: after the deadline
A8: PERT lambda | B8: 4 | C8: - | D8: standard Beta-PERT weight; the tool's default
A11: Risk id | B11: Name | C11: p (probability) | D11: a (min, days) | E11: m (mode, days) | F11: b (max, days)
A12: R-MAT | B12: Brick / material shortage | C12: 0.5 | D12: 1 | E12: 3 | F12: 8
A13: R-LAB | B13: Labour absenteeism / shortage | C13: 0.35 | D13: 1 | E13: 2 | F13: 6
A14: R-RWK | B14: Rework due to workmanship | C14: 0.25 | D14: 1 | E14: 2 | F14: 5
A15: R-WX | B15: Rain / monsoon stoppage | C15: 0.2 | D15: 1 | E15: 2 | F15: 7
A16: R-PLAN | B16: Poor planning or unrealistic scheduling | C16: 0.1 | D16: 1 | E16: 1 | F16: 3
A17: R-SAFE | B17: Unsafe conditions / work at height | C17: 0.3 | D17: 1 | E17: 2 | F17: 6
A18: R-SKILL | B18: Unskilled or unqualified labour | C18: 0.22 | D18: 1 | E18: 2 | F18: 5
A21: Response id | B21: Targets risk | C21: Cost (INR) | D21: p after | E21: Delay after a | F21: Delay after m | G21: Delay after b | H21: Secondary p | I21: Secondary a | J21: Secondary m | K21: Secondary b | L21: Feasible?
A22: M-BUF | B22: R-MAT | C22: 6000 | D22: 0.2 | L22: Yes
A23: M-SUP | B23: R-MAT | C23: 3000 | D23: 0.35 | L23: Yes
A24: M-GANG | B24: R-LAB | C24: 9000 | E24: 0 | F24: 1 | G24: 3 | H24: 0.3 | I24: 0 | J24: 1 | K24: 2 | L24: Yes
A25: M-COV | B25: R-WX | C25: 2500 | D25: 0.12 | L25: Yes
A26: M-QC | B26: R-RWK | C26: 1500 | D26: 0.15 | L26: Yes
A27: M-MECH | B27: R-SKILL | C27: 4000 | D27: 0.1 | L27: No
A29: Matrix settings
A30: Probability class edges (lower-edge inclusive) | B30: 0.2 | C30: 0.4 | D30: 0.6 | E30: 0.8
A31: Impact edges (fraction of T0) | B31: 0.02 | C31: 0.05 | D31: 0.1 | E31: 0.2
A32: Level cut-offs on score (Low <=, Moderate <=, High <=) | B32: 5 | C32: 10 | D32: 15

Sheet Risk_Calc
A1: Per-risk hand calculation vs tool
A3: Risk id | B3: p | C3: Mean delay (d) =(a+lam*m+b)/(lam+2) | D3: Variance (d^2) =(mean-a)(b-mean)/(lam+3) | E3: EMV (INR) =p*mean*Cd | F3: p x mean (d) | G3: Var contribution =p(var+mean^2)-(p mean)^2 | H3: 1 - p | I3: Tool mean | J3: Tool EMV (INR) | K3: Mean diff | L3: EMV diff (INR) | M3: Result
A4: =Inputs!A12 -> R-MAT | B4: =Inputs!C12 -> 0.5 | C4: =(Inputs!D12+Inputs!$B$8*Inputs!E12+Inputs!F12)/(Inputs!$B$8+2) -> 3.5 | D4: =(C4-Inputs!D12)*(Inputs!F12-C4)/(Inputs!$B$8+3) -> 1.6071429 | E4: =B4*C4*Inputs!$B$6 -> 14000 | F4: =B4*C4 -> 1.75 | G4: =B4*(D4+C4^2)-F4^2 -> 3.8660714 | H4: =1-B4 -> 0.5 | I4: 3.5 | J4: 14000 | K4: =C4-I4 -> 0 | L4: =E4-J4 -> 0 | M4: =IF(AND(ABS(K4)<=0.000001,ABS(L4)<=0.0001),"PASS","FAIL") -> PASS
A5: =Inputs!A13 -> R-LAB | B5: =Inputs!C13 -> 0.35 | C5: =(Inputs!D13+Inputs!$B$8*Inputs!E13+Inputs!F13)/(Inputs!$B$8+2) -> 2.5 | D5: =(C5-Inputs!D13)*(Inputs!F13-C5)/(Inputs!$B$8+3) -> 0.75 | E5: =B5*C5*Inputs!$B$6 -> 7000 | F5: =B5*C5 -> 0.875 | G5: =B5*(D5+C5^2)-F5^2 -> 1.684375 | H5: =1-B5 -> 0.65 | I5: 2.5 | J5: 7000 | K5: =C5-I5 -> 0 | L5: =E5-J5 -> 0 | M5: =IF(AND(ABS(K5)<=0.000001,ABS(L5)<=0.0001),"PASS","FAIL") -> PASS
A6: =Inputs!A14 -> R-RWK | B6: =Inputs!C14 -> 0.25 | C6: =(Inputs!D14+Inputs!$B$8*Inputs!E14+Inputs!F14)/(Inputs!$B$8+2) -> 2.3333333 | D6: =(C6-Inputs!D14)*(Inputs!F14-C6)/(Inputs!$B$8+3) -> 0.50793651 | E6: =B6*C6*Inputs!$B$6 -> 4666.6667 | F6: =B6*C6 -> 0.58333333 | G6: =B6*(D6+C6^2)-F6^2 -> 1.1478175 | H6: =1-B6 -> 0.75 | I6: 2.3333333 | J6: 4666.6667 | K6: =C6-I6 -> 0 | L6: =E6-J6 -> 0 | M6: =IF(AND(ABS(K6)<=0.000001,ABS(L6)<=0.0001),"PASS","FAIL") -> PASS
A7: =Inputs!A15 -> R-WX | B7: =Inputs!C15 -> 0.2 | C7: =(Inputs!D15+Inputs!$B$8*Inputs!E15+Inputs!F15)/(Inputs!$B$8+2) -> 2.6666667 | D7: =(C7-Inputs!D15)*(Inputs!F15-C7)/(Inputs!$B$8+3) -> 1.031746 | E7: =B7*C7*Inputs!$B$6 -> 4266.6667 | F7: =B7*C7 -> 0.53333333 | G7: =B7*(D7+C7^2)-F7^2 -> 1.344127 | H7: =1-B7 -> 0.8 | I7: 2.6666667 | J7: 4266.6667 | K7: =C7-I7 -> 0 | L7: =E7-J7 -> 0 | M7: =IF(AND(ABS(K7)<=0.000001,ABS(L7)<=0.0001),"PASS","FAIL") -> PASS
A8: =Inputs!A16 -> R-PLAN | B8: =Inputs!C16 -> 0.1 | C8: =(Inputs!D16+Inputs!$B$8*Inputs!E16+Inputs!F16)/(Inputs!$B$8+2) -> 1.3333333 | D8: =(C8-Inputs!D16)*(Inputs!F16-C8)/(Inputs!$B$8+3) -> 0.079365079 | E8: =B8*C8*Inputs!$B$6 -> 1066.6667 | F8: =B8*C8 -> 0.13333333 | G8: =B8*(D8+C8^2)-F8^2 -> 0.16793651 | H8: =1-B8 -> 0.9 | I8: 1.3333333 | J8: 1066.6667 | K8: =C8-I8 -> 0 | L8: =E8-J8 -> 0 | M8: =IF(AND(ABS(K8)<=0.000001,ABS(L8)<=0.0001),"PASS","FAIL") -> PASS
A9: =Inputs!A17 -> R-SAFE | B9: =Inputs!C17 -> 0.3 | C9: =(Inputs!D17+Inputs!$B$8*Inputs!E17+Inputs!F17)/(Inputs!$B$8+2) -> 2.5 | D9: =(C9-Inputs!D17)*(Inputs!F17-C9)/(Inputs!$B$8+3) -> 0.75 | E9: =B9*C9*Inputs!$B$6 -> 6000 | F9: =B9*C9 -> 0.75 | G9: =B9*(D9+C9^2)-F9^2 -> 1.5375 | H9: =1-B9 -> 0.7 | I9: 2.5 | J9: 6000 | K9: =C9-I9 -> 0 | L9: =E9-J9 -> 0 | M9: =IF(AND(ABS(K9)<=0.000001,ABS(L9)<=0.0001),"PASS","FAIL") -> PASS
A10: =Inputs!A18 -> R-SKILL | B10: =Inputs!C18 -> 0.22 | C10: =(Inputs!D18+Inputs!$B$8*Inputs!E18+Inputs!F18)/(Inputs!$B$8+2) -> 2.3333333 | D10: =(C10-Inputs!D18)*(Inputs!F18-C10)/(Inputs!$B$8+3) -> 0.50793651 | E10: =B10*C10*Inputs!$B$6 -> 4106.6667 | F10: =B10*C10 -> 0.51333333 | G10: =B10*(D10+C10^2)-F10^2 -> 1.0460127 | H10: =1-B10 -> 0.78 | I10: 2.3333333 | J10: 4106.6667 | K10: =C10-I10 -> 0 | L10: =E10-J10 -> 0 | M10: =IF(AND(ABS(K10)<=0.000001,ABS(L10)<=0.0001),"PASS","FAIL") -> PASS
A12: Totals | B12: Hand (formula) | C12: Tool / exact | D12: Difference | E12: Result
A13: Expected total delay E[D] (d) | B13: =SUM(F4:F10) -> 5.1383333 | C13: 5.1383333 | D13: =B13-C13 -> 0 | E13: =IF(ABS(D13)<=0.0001,"PASS","FAIL") -> PASS
A14: Variance of total delay (d^2) | B14: =SUM(G4:G10) -> 10.79384 | C14: 10.79384 | D14: =B14-C14 -> 0 | E14: =IF(ABS(D14)<=0.0001,"PASS","FAIL") -> PASS
A15: Standard deviation (d) | B15: =SQRT(B14) -> 3.285398 | C15: 3.285398 | D15: =B15-C15 -> 0 | E15: =IF(ABS(D15)<=0.0001,"PASS","FAIL") -> PASS
A16: Sum of event EMV (INR) | B16: =SUM(E4:E10) -> 41106.667 | C16: 41106.667 | D16: =B16-C16 -> 0 | E16: =IF(ABS(D16)<=0.0001,"PASS","FAIL") -> PASS
A17: P(at least one delay) =1-PRODUCT(1-p) | B17: =1-PRODUCT(H4:H10) -> 0.904177 | C17: 0.904177 | D17: =B17-C17 -> 0 | E17: =IF(ABS(D17)<=0.0001,"PASS","FAIL") -> PASS
A18: Planned duration + E[D] (d) | B18: =Inputs!B4+B13 -> 21.138333
A21: Note: Var contribution uses E[(I*D)^2] = p(var+mean^2) and the independent-occurrence assumption (no correlation), the case the tool runs by default. Tool values are from the validation run; the tool variance is the closed form used in the tool's own tests.

Sheet Matrix
A1: 5 x 5 matrix class and level by hand vs tool
A3: Risk id | B3: p | C3: Mean delay (d) | D3: Ratio = mean / T0 | E3: Probability class =1+count(p>=edge) | F3: Impact class =1+count(ratio>=edge) | G3: Score = pc x ic | H3: Level (hand) | I3: Tool pc | J3: Tool ic | K3: Tool score | L3: Tool level | M3: Result
A4: =Risk_Calc!A4 -> R-MAT | B4: =Risk_Calc!B4 -> 0.5 | C4: =Risk_Calc!C4 -> 3.5 | D4: =C4/Inputs!$B$4 -> 0.21875 | E4: =1+(B4>=Inputs!$B$30-0.000000000001)+(B4>=Inputs!$C$30-0.000000000001)+(B4>=Inputs!$D$30-0.000000000001)+(B4>=Inputs!$E$30-0.000000000001) -> 3 | F4: =1+(D4>=Inputs!$B$31-0.000000000001)+(D4>=Inputs!$C$31-0.000000000001)+(D4>=Inputs!$D$31-0.000000000001)+(D4>=Inputs!$E$31-0.000000000001) -> 5 | G4: =E4*F4 -> 15 | H4: =IF(G4<=Inputs!$B$32,"Low",IF(G4<=Inputs!$C$32,"Moderate",IF(G4<=Inputs!$D$32,"High","Extreme"))) -> High | I4: 3 | J4: 5 | K4: 15 | L4: High | M4: =IF(AND(E4=I4,F4=J4,G4=K4,H4=L4),"PASS","FAIL") -> PASS
A5: =Risk_Calc!A5 -> R-LAB | B5: =Risk_Calc!B5 -> 0.35 | C5: =Risk_Calc!C5 -> 2.5 | D5: =C5/Inputs!$B$4 -> 0.15625 | E5: =1+(B5>=Inputs!$B$30-0.000000000001)+(B5>=Inputs!$C$30-0.000000000001)+(B5>=Inputs!$D$30-0.000000000001)+(B5>=Inputs!$E$30-0.000000000001) -> 2 | F5: =1+(D5>=Inputs!$B$31-0.000000000001)+(D5>=Inputs!$C$31-0.000000000001)+(D5>=Inputs!$D$31-0.000000000001)+(D5>=Inputs!$E$31-0.000000000001) -> 4 | G5: =E5*F5 -> 8 | H5: =IF(G5<=Inputs!$B$32,"Low",IF(G5<=Inputs!$C$32,"Moderate",IF(G5<=Inputs!$D$32,"High","Extreme"))) -> Moderate | I5: 2 | J5: 4 | K5: 8 | L5: Moderate | M5: =IF(AND(E5=I5,F5=J5,G5=K5,H5=L5),"PASS","FAIL") -> PASS
A6: =Risk_Calc!A6 -> R-RWK | B6: =Risk_Calc!B6 -> 0.25 | C6: =Risk_Calc!C6 -> 2.3333333 | D6: =C6/Inputs!$B$4 -> 0.14583333 | E6: =1+(B6>=Inputs!$B$30-0.000000000001)+(B6>=Inputs!$C$30-0.000000000001)+(B6>=Inputs!$D$30-0.000000000001)+(B6>=Inputs!$E$30-0.000000000001) -> 2 | F6: =1+(D6>=Inputs!$B$31-0.000000000001)+(D6>=Inputs!$C$31-0.000000000001)+(D6>=Inputs!$D$31-0.000000000001)+(D6>=Inputs!$E$31-0.000000000001) -> 4 | G6: =E6*F6 -> 8 | H6: =IF(G6<=Inputs!$B$32,"Low",IF(G6<=Inputs!$C$32,"Moderate",IF(G6<=Inputs!$D$32,"High","Extreme"))) -> Moderate | I6: 2 | J6: 4 | K6: 8 | L6: Moderate | M6: =IF(AND(E6=I6,F6=J6,G6=K6,H6=L6),"PASS","FAIL") -> PASS
A7: =Risk_Calc!A7 -> R-WX | B7: =Risk_Calc!B7 -> 0.2 | C7: =Risk_Calc!C7 -> 2.6666667 | D7: =C7/Inputs!$B$4 -> 0.16666667 | E7: =1+(B7>=Inputs!$B$30-0.000000000001)+(B7>=Inputs!$C$30-0.000000000001)+(B7>=Inputs!$D$30-0.000000000001)+(B7>=Inputs!$E$30-0.000000000001) -> 2 | F7: =1+(D7>=Inputs!$B$31-0.000000000001)+(D7>=Inputs!$C$31-0.000000000001)+(D7>=Inputs!$D$31-0.000000000001)+(D7>=Inputs!$E$31-0.000000000001) -> 4 | G7: =E7*F7 -> 8 | H7: =IF(G7<=Inputs!$B$32,"Low",IF(G7<=Inputs!$C$32,"Moderate",IF(G7<=Inputs!$D$32,"High","Extreme"))) -> Moderate | I7: 2 | J7: 4 | K7: 8 | L7: Moderate | M7: =IF(AND(E7=I7,F7=J7,G7=K7,H7=L7),"PASS","FAIL") -> PASS
A8: =Risk_Calc!A8 -> R-PLAN | B8: =Risk_Calc!B8 -> 0.1 | C8: =Risk_Calc!C8 -> 1.3333333 | D8: =C8/Inputs!$B$4 -> 0.083333333 | E8: =1+(B8>=Inputs!$B$30-0.000000000001)+(B8>=Inputs!$C$30-0.000000000001)+(B8>=Inputs!$D$30-0.000000000001)+(B8>=Inputs!$E$30-0.000000000001) -> 1 | F8: =1+(D8>=Inputs!$B$31-0.000000000001)+(D8>=Inputs!$C$31-0.000000000001)+(D8>=Inputs!$D$31-0.000000000001)+(D8>=Inputs!$E$31-0.000000000001) -> 3 | G8: =E8*F8 -> 3 | H8: =IF(G8<=Inputs!$B$32,"Low",IF(G8<=Inputs!$C$32,"Moderate",IF(G8<=Inputs!$D$32,"High","Extreme"))) -> Low | I8: 1 | J8: 3 | K8: 3 | L8: Low | M8: =IF(AND(E8=I8,F8=J8,G8=K8,H8=L8),"PASS","FAIL") -> PASS
A9: =Risk_Calc!A9 -> R-SAFE | B9: =Risk_Calc!B9 -> 0.3 | C9: =Risk_Calc!C9 -> 2.5 | D9: =C9/Inputs!$B$4 -> 0.15625 | E9: =1+(B9>=Inputs!$B$30-0.000000000001)+(B9>=Inputs!$C$30-0.000000000001)+(B9>=Inputs!$D$30-0.000000000001)+(B9>=Inputs!$E$30-0.000000000001) -> 2 | F9: =1+(D9>=Inputs!$B$31-0.000000000001)+(D9>=Inputs!$C$31-0.000000000001)+(D9>=Inputs!$D$31-0.000000000001)+(D9>=Inputs!$E$31-0.000000000001) -> 4 | G9: =E9*F9 -> 8 | H9: =IF(G9<=Inputs!$B$32,"Low",IF(G9<=Inputs!$C$32,"Moderate",IF(G9<=Inputs!$D$32,"High","Extreme"))) -> Moderate | I9: 2 | J9: 4 | K9: 8 | L9: Moderate | M9: =IF(AND(E9=I9,F9=J9,G9=K9,H9=L9),"PASS","FAIL") -> PASS
A10: =Risk_Calc!A10 -> R-SKILL | B10: =Risk_Calc!B10 -> 0.22 | C10: =Risk_Calc!C10 -> 2.3333333 | D10: =C10/Inputs!$B$4 -> 0.14583333 | E10: =1+(B10>=Inputs!$B$30-0.000000000001)+(B10>=Inputs!$C$30-0.000000000001)+(B10>=Inputs!$D$30-0.000000000001)+(B10>=Inputs!$E$30-0.000000000001) -> 2 | F10: =1+(D10>=Inputs!$B$31-0.000000000001)+(D10>=Inputs!$C$31-0.000000000001)+(D10>=Inputs!$D$31-0.000000000001)+(D10>=Inputs!$E$31-0.000000000001) -> 4 | G10: =E10*F10 -> 8 | H10: =IF(G10<=Inputs!$B$32,"Low",IF(G10<=Inputs!$C$32,"Moderate",IF(G10<=Inputs!$D$32,"High","Extreme"))) -> Moderate | I10: 2 | J10: 4 | K10: 8 | L10: Moderate | M10: =IF(AND(E10=I10,F10=J10,G10=K10,H10=L10),"PASS","FAIL") -> PASS
A13: Exhaustive check in the validation run: 0 of 20,010 probability-class, 0 of 20,004 impact-class and 0 of 25 level mismatches (All_Checks, V5). Edges are lower-edge inclusive; the edge tolerance is 1e-12.

Sheet Mitigation_Calc
A1: Net benefit of each response, by hand vs tool
A3: Response | B3: Targets | C3: EMV before (INR) | D3: Mean delay after (d) | E3: p after | F3: EMV after (INR) | G3: Secondary EMV (INR) | H3: Cost (INR) | I3: Net benefit (INR) =before-after-secondary-cost | J3: Break-even reduction =cost/EMV before | K3: Pays? | L3: Feasible? | M3: Tool net (INR) | N3: Tool break-even | O3: Net diff | P3: Result
A4: =Inputs!A22 -> M-BUF | B4: =Inputs!B22 -> R-MAT | C4: =INDEX(Risk_Calc!$E$4:$E$10,MATCH(B4,Risk_Calc!$A$4:$A$10,0)) -> 14000 | D4: =IF(ISNUMBER(Inputs!E22),(Inputs!E22+Inputs!$B$8*Inputs!F22+Inputs!G22)/(Inputs!$B$8+2),INDEX(Risk_Calc!$C$4:$C$10,MATCH(B4,Risk_Calc!$A$4:$A$10,0))) -> 3.5 | E4: =IF(ISNUMBER(Inputs!D22),Inputs!D22,INDEX(Risk_Calc!$B$4:$B$10,MATCH(B4,Risk_Calc!$A$4:$A$10,0))) -> 0.2 | F4: =E4*D4*Inputs!$B$6 -> 5600 | G4: =IF(ISNUMBER(Inputs!H22),Inputs!H22*(Inputs!I22+Inputs!$B$8*Inputs!J22+Inputs!K22)/(Inputs!$B$8+2)*Inputs!$B$6,0) -> 0 | H4: =Inputs!C22 -> 6000 | I4: =C4-F4-G4-H4 -> 2400 | J4: =H4/C4 -> 0.42857143 | K4: =IF(I4>0,"Yes","No") -> Yes | L4: =Inputs!L22 -> Yes | M4: 2400 | N4: 0.42857143 | O4: =I4-M4 -> 0 | P4: =IF(AND(ABS(O4)<=0.01,ABS(J4-N4)<=0.000001),"PASS","FAIL") -> PASS
A5: =Inputs!A23 -> M-SUP | B5: =Inputs!B23 -> R-MAT | C5: =INDEX(Risk_Calc!$E$4:$E$10,MATCH(B5,Risk_Calc!$A$4:$A$10,0)) -> 14000 | D5: =IF(ISNUMBER(Inputs!E23),(Inputs!E23+Inputs!$B$8*Inputs!F23+Inputs!G23)/(Inputs!$B$8+2),INDEX(Risk_Calc!$C$4:$C$10,MATCH(B5,Risk_Calc!$A$4:$A$10,0))) -> 3.5 | E5: =IF(ISNUMBER(Inputs!D23),Inputs!D23,INDEX(Risk_Calc!$B$4:$B$10,MATCH(B5,Risk_Calc!$A$4:$A$10,0))) -> 0.35 | F5: =E5*D5*Inputs!$B$6 -> 9800 | G5: =IF(ISNUMBER(Inputs!H23),Inputs!H23*(Inputs!I23+Inputs!$B$8*Inputs!J23+Inputs!K23)/(Inputs!$B$8+2)*Inputs!$B$6,0) -> 0 | H5: =Inputs!C23 -> 3000 | I5: =C5-F5-G5-H5 -> 1200 | J5: =H5/C5 -> 0.21428571 | K5: =IF(I5>0,"Yes","No") -> Yes | L5: =Inputs!L23 -> Yes | M5: 1200 | N5: 0.21428571 | O5: =I5-M5 -> 0 | P5: =IF(AND(ABS(O5)<=0.01,ABS(J5-N5)<=0.000001),"PASS","FAIL") -> PASS
A6: =Inputs!A24 -> M-GANG | B6: =Inputs!B24 -> R-LAB | C6: =INDEX(Risk_Calc!$E$4:$E$10,MATCH(B6,Risk_Calc!$A$4:$A$10,0)) -> 7000 | D6: =IF(ISNUMBER(Inputs!E24),(Inputs!E24+Inputs!$B$8*Inputs!F24+Inputs!G24)/(Inputs!$B$8+2),INDEX(Risk_Calc!$C$4:$C$10,MATCH(B6,Risk_Calc!$A$4:$A$10,0))) -> 1.1666667 | E6: =IF(ISNUMBER(Inputs!D24),Inputs!D24,INDEX(Risk_Calc!$B$4:$B$10,MATCH(B6,Risk_Calc!$A$4:$A$10,0))) -> 0.35 | F6: =E6*D6*Inputs!$B$6 -> 3266.6667 | G6: =IF(ISNUMBER(Inputs!H24),Inputs!H24*(Inputs!I24+Inputs!$B$8*Inputs!J24+Inputs!K24)/(Inputs!$B$8+2)*Inputs!$B$6,0) -> 2400 | H6: =Inputs!C24 -> 9000 | I6: =C6-F6-G6-H6 -> -7666.6667 | J6: =H6/C6 -> 1.2857143 | K6: =IF(I6>0,"Yes","No") -> No | L6: =Inputs!L24 -> Yes | M6: -7666.6667 | N6: 1.2857143 | O6: =I6-M6 -> 0 | P6: =IF(AND(ABS(O6)<=0.01,ABS(J6-N6)<=0.000001),"PASS","FAIL") -> PASS
A7: =Inputs!A25 -> M-COV | B7: =Inputs!B25 -> R-WX | C7: =INDEX(Risk_Calc!$E$4:$E$10,MATCH(B7,Risk_Calc!$A$4:$A$10,0)) -> 4266.6667 | D7: =IF(ISNUMBER(Inputs!E25),(Inputs!E25+Inputs!$B$8*Inputs!F25+Inputs!G25)/(Inputs!$B$8+2),INDEX(Risk_Calc!$C$4:$C$10,MATCH(B7,Risk_Calc!$A$4:$A$10,0))) -> 2.6666667 | E7: =IF(ISNUMBER(Inputs!D25),Inputs!D25,INDEX(Risk_Calc!$B$4:$B$10,MATCH(B7,Risk_Calc!$A$4:$A$10,0))) -> 0.12 | F7: =E7*D7*Inputs!$B$6 -> 2560 | G7: =IF(ISNUMBER(Inputs!H25),Inputs!H25*(Inputs!I25+Inputs!$B$8*Inputs!J25+Inputs!K25)/(Inputs!$B$8+2)*Inputs!$B$6,0) -> 0 | H7: =Inputs!C25 -> 2500 | I7: =C7-F7-G7-H7 -> -793.33333 | J7: =H7/C7 -> 0.5859375 | K7: =IF(I7>0,"Yes","No") -> No | L7: =Inputs!L25 -> Yes | M7: -793.33333 | N7: 0.5859375 | O7: =I7-M7 -> 0 | P7: =IF(AND(ABS(O7)<=0.01,ABS(J7-N7)<=0.000001),"PASS","FAIL") -> PASS
A8: =Inputs!A26 -> M-QC | B8: =Inputs!B26 -> R-RWK | C8: =INDEX(Risk_Calc!$E$4:$E$10,MATCH(B8,Risk_Calc!$A$4:$A$10,0)) -> 4666.6667 | D8: =IF(ISNUMBER(Inputs!E26),(Inputs!E26+Inputs!$B$8*Inputs!F26+Inputs!G26)/(Inputs!$B$8+2),INDEX(Risk_Calc!$C$4:$C$10,MATCH(B8,Risk_Calc!$A$4:$A$10,0))) -> 2.3333333 | E8: =IF(ISNUMBER(Inputs!D26),Inputs!D26,INDEX(Risk_Calc!$B$4:$B$10,MATCH(B8,Risk_Calc!$A$4:$A$10,0))) -> 0.15 | F8: =E8*D8*Inputs!$B$6 -> 2800 | G8: =IF(ISNUMBER(Inputs!H26),Inputs!H26*(Inputs!I26+Inputs!$B$8*Inputs!J26+Inputs!K26)/(Inputs!$B$8+2)*Inputs!$B$6,0) -> 0 | H8: =Inputs!C26 -> 1500 | I8: =C8-F8-G8-H8 -> 366.66667 | J8: =H8/C8 -> 0.32142857 | K8: =IF(I8>0,"Yes","No") -> Yes | L8: =Inputs!L26 -> Yes | M8: 366.66667 | N8: 0.32142857 | O8: =I8-M8 -> 0 | P8: =IF(AND(ABS(O8)<=0.01,ABS(J8-N8)<=0.000001),"PASS","FAIL") -> PASS
A9: =Inputs!A27 -> M-MECH | B9: =Inputs!B27 -> R-SKILL | C9: =INDEX(Risk_Calc!$E$4:$E$10,MATCH(B9,Risk_Calc!$A$4:$A$10,0)) -> 4106.6667 | D9: =IF(ISNUMBER(Inputs!E27),(Inputs!E27+Inputs!$B$8*Inputs!F27+Inputs!G27)/(Inputs!$B$8+2),INDEX(Risk_Calc!$C$4:$C$10,MATCH(B9,Risk_Calc!$A$4:$A$10,0))) -> 2.3333333 | E9: =IF(ISNUMBER(Inputs!D27),Inputs!D27,INDEX(Risk_Calc!$B$4:$B$10,MATCH(B9,Risk_Calc!$A$4:$A$10,0))) -> 0.1 | F9: =E9*D9*Inputs!$B$6 -> 1866.6667 | G9: =IF(ISNUMBER(Inputs!H27),Inputs!H27*(Inputs!I27+Inputs!$B$8*Inputs!J27+Inputs!K27)/(Inputs!$B$8+2)*Inputs!$B$6,0) -> 0 | H9: =Inputs!C27 -> 4000 | I9: =C9-F9-G9-H9 -> -1760 | J9: =H9/C9 -> 0.97402597 | K9: =IF(I9>0,"Yes","No") -> No | L9: =Inputs!L27 -> No | M9: -1760 | N9: 0.97402597 | O9: =I9-M9 -> 0 | P9: =IF(AND(ABS(O9)<=0.01,ABS(J9-N9)<=0.000001),"PASS","FAIL") -> PASS
A11: Reading: a response pays when the EMV it removes exceeds its cost plus any secondary risk it creates. M-MECH is marked not feasible in the case, so the tool keeps it out of the options even though its arithmetic net benefit is shown here.

Sheet Options
A1: All 23 options: exact total expected cost (TEC) vs tool
A2: Residual expected cost and exact P90 come from numerical convolution of the mixture distributions (pasted values, blue). TEC, ranks, z-scores and the decision are formulas.
A4: Option | B4: Mitigation cost (INR) | C4: Exact residual E[cost] (INR) | D4: Exact TEC (INR) =mit cost + residual | E4: Rank among feasible (1 = lowest TEC) | F4: Tool TEC n=10,000 (INR) | G4: Tool TEC n=200,000 (INR) | H4: Standard error n=200k (INR) | I4: z-score n=200k =(tool-exact)/SE | J4: Exact P90 (d) | K4: Tool P90 n=200k (d) | L4: Exact P(finish > deadline) | M4: Tool P(exceed) n=200k | N4: Feasible? | O4: |z| <= 4?
A5: ACCEPT | B5: 0 | C5: 50792.737 | D5: =B5+C5 -> 50792.737 | E5: =IF(N5="Yes",COUNTIFS($N$5:$N$27,"Yes",$D$5:$D$27,"<"&D5)+1,"-") -> 11 | F5: 50821.048 | G5: 50960.927 | H5: 85.356366 | I5: =(G5-D5)/H5 -> 1.9704414 | J5: 25.567684 | K5: 25.585208 | L5: 0.6018512 | M5: 0.604075 | N5: Yes | O5: =IF(ABS(I5)<=4,"PASS","FAIL") -> PASS
A6: O-M-BUF | B6: 6000 | C6: 39008.178 | D6: =B6+C6 -> 45008.178 | E6: =IF(N6="Yes",COUNTIFS($N$5:$N$27,"Yes",$D$5:$D$27,"<"&D6)+1,"-") -> 3 | F6: 44929.427 | G6: 45197.684 | H6: 75.869355 | I6: =(G6-D6)/H6 -> 2.4977951 | J6: 24.233616 | K6: 24.276544 | L6: 0.46300177 | M6: 0.464895 | N6: Yes | O6: =IF(ABS(I6)<=4,"PASS","FAIL") -> PASS
A7: O-M-SUP | B7: 3000 | C7: 44900.458 | D7: =B7+C7 -> 47900.458 | E7: =IF(N7="Yes",COUNTIFS($N$5:$N$27,"Yes",$D$5:$D$27,"<"&D7)+1,"-") -> 7 | F7: 48045.51 | G7: 48083.184 | H7: 81.811065 | I7: =(G7-D7)/H7 -> 2.2335163 | J7: 24.980614 | K7: 25.005941 | L7: 0.53242649 | M7: 0.53509 | N7: Yes | O7: =IF(ABS(I7)<=4,"PASS","FAIL") -> PASS
A8: O-M-GANG | B8: 9000 | C8: 48661.154 | D8: =B8+C8 -> 57661.154 | E8: =IF(N8="Yes",COUNTIFS($N$5:$N$27,"Yes",$D$5:$D$27,"<"&D8)+1,"-") -> 21 | F8: 57736.62 | G8: 57817.042 | H8: 80.828382 | I8: =(G8-D8)/H8 -> 1.9286338 | J8: 25.195087 | K8: 25.212097 | L8: 0.58727408 | M8: 0.58889 | N8: Yes | O8: =IF(ABS(I8)<=4,"PASS","FAIL") -> PASS
A9: O-M-COV | B9: 2500 | C9: 48318.429 | D9: =B9+C9 -> 50818.429 | E9: =IF(N9="Yes",COUNTIFS($N$5:$N$27,"Yes",$D$5:$D$27,"<"&D9)+1,"-") -> 12 | F9: 50770.295 | G9: 51012.589 | H9: 82.776324 | I9: =(G9-D9)/H9 -> 2.3455958 | J9: 25.260311 | K9: 25.286577 | L9: 0.57848134 | M9: 0.580885 | N9: Yes | O9: =IF(ABS(I9)<=4,"PASS","FAIL") -> PASS
A10: O-M-QC | B10: 1500 | C10: 48123.944 | D10: =B10+C10 -> 49623.944 | E10: =IF(N10="Yes",COUNTIFS($N$5:$N$27,"Yes",$D$5:$D$27,"<"&D10)+1,"-") -> 9 | F10: 49518.366 | G10: 49753.372 | H10: 83.034327 | I10: =(G10-D10)/H10 -> 1.5587264 | J10: 25.261891 | K10: 25.282067 | L10: 0.57499068 | M10: 0.576455 | N10: Yes | O10: =IF(ABS(I10)<=4,"PASS","FAIL") -> PASS
A11: O-M-BUF+M-GANG | B11: 15000 | C11: 36944.314 | D11: =B11+C11 -> 51944.314 | E11: =IF(N11="Yes",COUNTIFS($N$5:$N$27,"Yes",$D$5:$D$27,"<"&D11)+1,"-") -> 14 | F11: 51932.509 | G11: 52123.22 | H11: 71.076299 | I11: =(G11-D11)/H11 -> 2.5170846 | J11: 23.848221 | K11: 23.887628 | L11: 0.43848951 | M11: 0.44001 | N11: Yes | O11: =IF(ABS(I11)<=4,"PASS","FAIL") -> PASS
A12: O-M-BUF+M-COV | B12: 8500 | C12: 36663.109 | D12: =B12+C12 -> 45163.109 | E12: =IF(N12="Yes",COUNTIFS($N$5:$N$27,"Yes",$D$5:$D$27,"<"&D12)+1,"-") -> 4 | F12: 45023.429 | G12: 45375.142 | H12: 73.120955 | I12: =(G12-D12)/H12 -> 2.899748 | J12: 23.919275 | K12: 23.967871 | L12: 0.43438568 | M12: 0.436835 | N12: Yes | O12: =IF(ABS(I12)<=4,"PASS","FAIL") -> PASS
A13: O-M-BUF+M-QC | B13: 7500 | C13: 36492.095 | D13: =B13+C13 -> 43992.095 | E13: =IF(N13="Yes",COUNTIFS($N$5:$N$27,"Yes",$D$5:$D$27,"<"&D13)+1,"-") -> 1 | F13: 43774.445 | G13: 44143.436 | H13: 73.451139 | I13: =(G13-D13)/H13 -> 2.0604238 | J13: 23.924309 | K13: 23.975331 | L13: 0.43128868 | M13: 0.43241 | N13: Yes | O13: =IF(ABS(I13)<=4,"PASS","FAIL") -> PASS
A14: O-M-SUP+M-GANG | B14: 12000 | C14: 42802.734 | D14: =B14+C14 -> 54802.734 | E14: =IF(N14="Yes",COUNTIFS($N$5:$N$27,"Yes",$D$5:$D$27,"<"&D14)+1,"-") -> 17 | F14: 55002.707 | G14: 54973.255 | H14: 77.223278 | I14: =(G14-D14)/H14 -> 2.208155 | J14: 24.609345 | K14: 24.630982 | L14: 0.5128818 | M14: 0.514895 | N14: Yes | O14: =IF(ABS(I14)<=4,"PASS","FAIL") -> PASS
A15: O-M-SUP+M-COV | B15: 5500 | C15: 42490.769 | D15: =B15+C15 -> 47990.769 | E15: =IF(N15="Yes",COUNTIFS($N$5:$N$27,"Yes",$D$5:$D$27,"<"&D15)+1,"-") -> 8 | F15: 48072.559 | G15: 48197.907 | H15: 79.160778 | I15: =(G15-D15)/H15 -> 2.6166791 | J15: 24.674051 | K15: 24.695722 | L15: 0.50643351 | M15: 0.50935 | N15: Yes | O15: =IF(ABS(I15)<=4,"PASS","FAIL") -> PASS
A16: O-M-SUP+M-QC | B16: 4500 | C16: 42308.02 | D16: =B16+C16 -> 46808.02 | E16: =IF(N16="Yes",COUNTIFS($N$5:$N$27,"Yes",$D$5:$D$27,"<"&D16)+1,"-") -> 5 | F16: 46805.28 | G16: 46951.981 | H16: 79.450255 | I16: =(G16-D16)/H16 -> 1.8119733 | J16: 24.675942 | K16: 24.700858 | L16: 0.50313968 | M16: 0.50504 | N16: Yes | O16: =IF(ABS(I16)<=4,"PASS","FAIL") -> PASS
... A27: O-M-MECH | B27: 4000 | C27: 47580.124 | D27: =B27+C27 -> 51580.124 | E27: =IF(N27="Yes",COUNTIFS($N$5:$N$27,"Yes",$D$5:$D$27,"<"&D27)+1,"-") -> - | F27: 51554.916 | G27: 51760.569 | H27: 82.371783 | I27: =(G27-D27)/H27 -> 2.1906103 | J27: 25.189483 | K27: 25.214866 | L27: 0.56996436 | M27: 0.572525 | N27: No | O27: =IF(ABS(I27)<=4,"PASS","FAIL") -> PASS
A29: Hand-best feasible option | B29: =INDEX($A$5:$A$27,MATCH(1,$E$5:$E$27,0)) -> O-M-BUF+M-QC
A30: Its exact TEC (INR) | B30: =INDEX($D$5:$D$27,MATCH(1,$E$5:$E$27,0)) -> 43992.095
A31: Tool's chosen option, n=10,000 | B31: O-M-BUF+M-QC
A32: Tool's chosen option, n=200,000 | B32: O-M-BUF+M-QC
A33: Decision agrees? | B33: =IF(AND(B29=B31,B29=B32),"PASS","FAIL") -> PASS
A34: Tool command at n=10,000 | B34: AUTHORIZE MITIGATION
A35: Gap: 2nd best minus best TEC (INR) | B35: =SUMPRODUCT(($E$5:$E$27=2)*$D$5:$D$27)-SUMPRODUCT(($E$5:$E$27=1)*$D$5:$D$27) -> 187.72217
A37: A gap of a few hundred INR between first and second option is small against a cost scale of about 44,000 INR: treat the choice between them as not firm. Largest |z| at n=200,000 is 2.97 for one of 23 options, consistent with chance (see Test_Summary).

Sheet Copula
A1: Occurrence correlation (Gaussian copula): joint probability vs bivariate-normal value
A3: rho | B3: Exact P(A and B) (bivariate normal) | C3: Tool P(A and B) | D3: Difference | E3: Tool marginal A | F3: Tool marginal B | G3: Result
A4: -0.5 | B4: 0.053484529 | C4: 0.053298333 | D4: =C4-B4 -> -0.00018619573 | E4: 0.39915667 | F4: 0.30019 | G4: =IF(ABS(D4)<=0.001,"PASS","FAIL") -> PASS
A5: 0 | B5: 0.12 | C5: 0.12007667 | D5: =C5-B5 -> 7.6666667e-05 | E5: 0.39915667 | F5: 0.30044167 | G5: =IF(ABS(D5)<=0.001,"PASS","FAIL") -> PASS
A6: 0.6 | B6: 0.20850391 | C6: 0.20837167 | D6: =C6-B6 -> -0.00013224404 | E6: 0.39915667 | F6: 0.30024167 | G6: =IF(ABS(D6)<=0.001,"PASS","FAIL") -> PASS
A7: 0.95 | B7: 0.28721887 | C7: 0.28686833 | D7: =C7-B7 -> -0.00035053565 | E7: 0.39915667 | F7: 0.2994 | G7: =IF(ABS(D7)<=0.001,"PASS","FAIL") -> PASS
A9: Independent case (rho = 0) must equal pA x pB by hand:
A10: pA x pB | B10: =0.4*0.3 -> 0.12 | C10: Marginals set to 0.40 and 0.30 in the test.

Sheet All_Checks
A1: All 242 checks of the hand-calculation run (9 Oct 2026, code before fixes F1-F6; F6 case in row for V11)
A3: Check id | B3: Description | C3: Hand / exact | D3: Tool | E3: |Difference| (formula) | F3: Tolerance | G3: Result (formula) | H3: Result in run | I3: Note
A4: V1-mean-PERT(1,3,8) | B4: mean PERT(1,3,8): hand vs tool formula | C4: 3.5 | D4: 3.5 | E4: =ABS(C4-D4) -> 0 | F4: 1e-12 | G4: =IF(E4<=F4,"PASS","FAIL") -> PASS | H4: PASS
A5: V1-var-PERT(1,3,8) | B5: variance PERT(1,3,8): hand vs tool formula | C5: 1.6071429 | D5: 1.6071429 | E5: =ABS(C5-D5) -> 0 | F5: 1e-12 | G5: =IF(E5<=F5,"PASS","FAIL") -> PASS | H5: PASS
A6: V1-qmean-PERT(1,3,8) | B6: mean PERT(1,3,8): hand vs integral of tool inverse-CDF | C6: 3.5 | D6: 3.5 | E6: =ABS(C6-D6) -> 2.6064022e-09 | F6: 0.0002 | G6: =IF(E6<=F6,"PASS","FAIL") -> PASS | H6: PASS
A7: V1-qvar-PERT(1,3,8) | B7: variance PERT(1,3,8): hand vs variance of tool inverse-CDF | C7: 1.6071429 | D7: 1.6071428 | E7: =ABS(C7-D7) -> 2.4277942e-08 | F7: 0.0032142857 | G7: =IF(E7<=F7,"PASS","FAIL") -> PASS | H7: PASS
A8: V1-cdf-PERT(1,3,8) | B8: inverse-CDF round trip via independent CDF PERT(1,3,8) | C8: 0 | D8: 9.9920072e-16 | E8: =ABS(C8-D8) -> 9.9920072e-16 | F8: 1e-05 | G8: =IF(E8<=F8,"PASS","FAIL") -> PASS | H8: PASS
A9: V1-mean-PERT(1,2,6) | B9: mean PERT(1,2,6): hand vs tool formula | C9: 2.5 | D9: 2.5 | E9: =ABS(C9-D9) -> 0 | F9: 1e-12 | G9: =IF(E9<=F9,"PASS","FAIL") -> PASS | H9: PASS
A10: V1-var-PERT(1,2,6) | B10: variance PERT(1,2,6): hand vs tool formula | C10: 0.75 | D10: 0.75 | E10: =ABS(C10-D10) -> 0 | F10: 1e-12 | G10: =IF(E10<=F10,"PASS","FAIL") -> PASS | H10: PASS
A11: V1-qmean-PERT(1,2,6) | B11: mean PERT(1,2,6): hand vs integral of tool inverse-CDF | C11: 2.5 | D11: 2.5 | E11: =ABS(C11-D11) -> 2.8332252e-09 | F11: 0.0002 | G11: =IF(E11<=F11,"PASS","FAIL") -> PASS | H11: PASS
A12: V1-qvar-PERT(1,2,6) | B12: variance PERT(1,2,6): hand vs variance of tool inverse-CDF | C12: 0.75 | D12: 0.74999998 | E12: =ABS(C12-D12) -> 1.9573453e-08 | F12: 0.002 | G12: =IF(E12<=F12,"PASS","FAIL") -> PASS | H12: PASS
A13: V1-cdf-PERT(1,2,6) | B13: inverse-CDF round trip via independent CDF PERT(1,2,6) | C13: 0 | D13: 9.9920072e-16 | E13: =ABS(C13-D13) -> 9.9920072e-16 | F13: 1e-05 | G13: =IF(E13<=F13,"PASS","FAIL") -> PASS | H13: PASS
A14: V1-mean-PERT(0,1,3) | B14: mean PERT(0,1,3): hand vs tool formula | C14: 1.1666667 | D14: 1.1666667 | E14: =ABS(C14-D14) -> 0 | F14: 1e-12 | G14: =IF(E14<=F14,"PASS","FAIL") -> PASS | H14: PASS
A15: V1-var-PERT(0,1,3) | B15: variance PERT(0,1,3): hand vs tool formula | C15: 0.30555556 | D15: 0.30555556 | E15: =ABS(C15-D15) -> 0 | F15: 1e-12 | G15: =IF(E15<=F15,"PASS","FAIL") -> PASS | H15: PASS
... A72: V3-grid-var | B72: grid-convolution variance vs closed form (validates the exact reference itself) | C72: 10.79384 | D72: 10.793844 | E72: =ABS(C72-D72) -> 3.5477868e-06 | F72: 0.02 | G72: =IF(E72<=F72,"PASS","FAIL") -> PASS | H72: PASS
A73: V3-grid-p0 | B73: P(no risk occurs) grid vs product(1-p) | C73: 0.095823 | D73: 0.095823 | E73: =ABS(C73-D73) -> 0 | F73: 0.0005 | G73: =IF(E73<=F73,"PASS","FAIL") -> PASS | H73: PASS | I73: mass at zero also contains tiny mass of delays < H/2, so tolerance 5e-4
A74: V3-TEC10-ACCEPT | B74: total expected cost ACCEPT (n=10k), |diff| <= 4 SE | C74: 50792.737 | D74: 50821.048 | E74: =ABS(C74-D74) -> 28.310671 | F74: 1547.0375 | G74: =IF(E74<=F74,"PASS","FAIL") -> PASS | H74: PASS
A75: V3-TEC200-ACCEPT | B75: total expected cost ACCEPT (n=200k), |diff| <= 4 SE | C75: 50792.737 | D75: 50960.927 | E75: =ABS(C75-D75) -> 168.18972 | F75: 341.42547 | G75: =IF(E75<=F75,"PASS","FAIL") -> PASS | H75: PASS
A76: V3-P90-ACCEPT | B76: P90 duration ACCEPT (n=200k): hand inside tool 95% CI (+0.02 d grid slack) | C76: 25.567684 | D76: 25.585208 | E76: =ABS(C76-D76) -> 0.017523837 | F76: 0.047850658 | G76: =IF(E76<=F76,"PASS","FAIL") -> PASS | H76: PASS
A77: V3-pexc-ACCEPT | B77: P(duration > deadline) ACCEPT (n=200k), |diff| <= 4 SE | C77: 0.6018512 | D77: 0.604075 | E77: =ABS(C77-D77) -> 0.0022237981 | F77: 0.0063741824 | G77: =IF(E77<=F77,"PASS","FAIL") -> PASS | H77: PASS
A78: V3-Edel-ACCEPT | B78: expected delay ACCEPT (n=200k) | C78: 5.1383331 | D78: 5.1520922 | E78: =ABS(C78-D78) -> 0.013759163 | F78: 0.06 | G78: =IF(E78<=F78,"PASS","FAIL") -> PASS | H78: PASS
A79: V3-TEC10-O-M-BUF | B79: total expected cost O-M-BUF (n=10k), |diff| <= 4 SE | C79: 45008.178 | D79: 44929.427 | E79: =ABS(C79-D79) -> 78.751466 | F79: 1364.7776 | G79: =IF(E79<=F79,"PASS","FAIL") -> PASS | H79: PASS
A80: V3-TEC200-O-M-BUF | B80: total expected cost O-M-BUF (n=200k), |diff| <= 4 SE | C80: 45008.178 | D80: 45197.684 | E80: =ABS(C80-D80) -> 189.50611 | F80: 303.47742 | G80: =IF(E80<=F80,"PASS","FAIL") -> PASS | H80: PASS
A81: V3-P90-O-M-BUF | B81: P90 duration O-M-BUF (n=200k): hand inside tool 95% CI (+0.02 d grid slack) | C81: 24.233616 | D81: 24.276544 | E81: =ABS(C81-D81) -> 0.042928622 | F81: 0.049670156 | G81: =IF(E81<=F81,"PASS","FAIL") -> PASS | H81: PASS
A82: V3-pexc-O-M-BUF | B82: P(duration > deadline) O-M-BUF (n=200k), |diff| <= 4 SE | C82: 0.46300177 | D82: 0.464895 | E82: =ABS(C82-D82) -> 0.0018932273 | F82: 0.0064610998 | G82: =IF(E82<=F82,"PASS","FAIL") -> PASS | H82: PASS
A83: V3-Edel-O-M-BUF | B83: expected delay O-M-BUF (n=200k) | C83: 4.0883331 | D83: 4.1040014 | E83: =ABS(C83-D83) -> 0.015668293 | F83: 0.06 | G83: =IF(E83<=F83,"PASS","FAIL") -> PASS | H83: PASS
A84: V3-TEC10-O-M-SUP | B84: total expected cost O-M-SUP (n=10k), |diff| <= 4 SE | C84: 47900.458 | D84: 48045.51 | E84: =ABS(C84-D84) -> 145.05185 | F84: 1490.5876 | G84: =IF(E84<=F84,"PASS","FAIL") -> PASS | H84: PASS
A85: V3-TEC200-O-M-SUP | B85: total expected cost O-M-SUP (n=200k), |diff| <= 4 SE | C85: 47900.458 | D85: 48083.184 | E85: =ABS(C85-D85) -> 182.72635 | F85: 327.24426 | G85: =IF(E85<=F85,"PASS","FAIL") -> PASS | H85: PASS
... A189: V3-seed2024 | B189: second seed n=200k: all |z| of TEC vs exact <= 4 | C189: 0 | D189: 1.0383069 | E189: =ABS(C189-D189) -> 1.0383069 | F189: 4 | G189: =IF(E189<=F189,"PASS","FAIL") -> PASS | H189: PASS
A190: V3-decision | B190: preferred option by hand == tool (n=200k) | C190: 0 | D190: 0 | E190: =ABS(C190-D190) -> 0 | F190: 0 | G190: =IF(E190<=F190,"PASS","FAIL") -> PASS | H190: PASS | I190: hand O-M-BUF+M-QC / tool O-M-BUF+M-QC
A191: V4-net-M-BUF | B191: net benefit M-BUF (INR) | C191: 2400 | D191: 2400 | E191: =ABS(C191-D191) -> 0 | F191: 1e-06 | G191: =IF(E191<=F191,"PASS","FAIL") -> PASS | H191: PASS
A192: V4-be-M-BUF | B192: break-even required reduction M-BUF | C192: 0.42857143 | D192: 0.42857143 | E192: =ABS(C192-D192) -> 0 | F192: 1e-12 | G192: =IF(E192<=F192,"PASS","FAIL") -> PASS | H192: PASS
A193: V4-pmax-M-BUF | B193: max p-after that still pays M-BUF | C193: 0.28571429 | D193: 0.28571429 | E193: =ABS(C193-D193) -> 0 | F193: 1e-12 | G193: =IF(E193<=F193,"PASS","FAIL") -> PASS | H193: PASS
A194: V4-net-M-SUP | B194: net benefit M-SUP (INR) | C194: 1200 | D194: 1200 | E194: =ABS(C194-D194) -> 0 | F194: 1e-06 | G194: =IF(E194<=F194,"PASS","FAIL") -> PASS | H194: PASS
A195: V4-be-M-SUP | B195: break-even required reduction M-SUP | C195: 0.21428571 | D195: 0.21428571 | E195: =ABS(C195-D195) -> 0 | F195: 1e-12 | G195: =IF(E195<=F195,"PASS","FAIL") -> PASS | H195: PASS
A196: V4-pmax-M-SUP | B196: max p-after that still pays M-SUP | C196: 0.39285714 | D196: 0.39285714 | E196: =ABS(C196-D196) -> 0 | F196: 1e-12 | G196: =IF(E196<=F196,"PASS","FAIL") -> PASS | H196: PASS
A197: V4-net-M-GANG | B197: net benefit M-GANG (INR) | C197: -7666.6667 | D197: -7666.6667 | E197: =ABS(C197-D197) -> 0 | F197: 1e-06 | G197: =IF(E197<=F197,"PASS","FAIL") -> PASS | H197: PASS
A198: V4-be-M-GANG | B198: break-even required reduction M-GANG | C198: 1.2857143 | D198: 1.2857143 | E198: =ABS(C198-D198) -> 0 | F198: 1e-12 | G198: =IF(E198<=F198,"PASS","FAIL") -> PASS | H198: PASS
A199: V4-net-M-COV | B199: net benefit M-COV (INR) | C199: -793.33333 | D199: -793.33333 | E199: =ABS(C199-D199) -> 0 | F199: 1e-06 | G199: =IF(E199<=F199,"PASS","FAIL") -> PASS | H199: PASS
A200: V4-be-M-COV | B200: break-even required reduction M-COV | C200: 0.5859375 | D200: 0.5859375 | E200: =ABS(C200-D200) -> 0 | F200: 1e-12 | G200: =IF(E200<=F200,"PASS","FAIL") -> PASS | H200: PASS
...

Sheet Test_Summary
A1: Test summary, 9 October 2026
A3: Test set | B3: Checks | C3: Passed before fixes | D3: Passed after fixes | E3: Failed after | F3: Cause of remaining failures
A4: Hand and exact calculation | B4: 242 | C4: 239 | D4: 240 | E4: =B4-D4 -> 2 | F4: Two P90 differences of 0.049 and 0.051 d at n=200,000: sampling noise
A5: CLI, API, front end, packaging flows | B5: 86 | C5: 79 | D5: 85 | E5: =B5-D5 -> 1 | F5: One wrong expectation in the test script (run on a case without a cost model exits 0 by design)
A6: Edge cases, wrong-shape inputs, performance | B6: 85 | C6: 68 | D6: 83 | E6: =B6-D6 -> 2 | F6: Two wrong expectations in the test script (lambda = 0 is correctly rejected; truncation notice is in the report)
A7: Total | B7: =SUM(B4:B6) -> 413 | C7: =SUM(C4:C6) -> 386 | D7: =SUM(D4:D6) -> 408 | E7: =B7-D7 -> 5
A9: Other test sets | B9: Size | C9: Before fixes | D9: After fixes | F9: Note
A10: Fuzzing, mutated inputs | B10: 7700 | C10: 12 unhandled errors | D10: 0 unhandled | F10: 4,000 register + 3,000 analysis-case + 700 run_analysis mutations
A11: Invariants on random valid cases | B11: 140 | C11: 140 held | D11: 140 held | F11: No valid case rejected
A12: Repository test suite | B12: 557 | C12: 522 passed, 3 skipped (of 525) | D12: 554 passed, 3 skipped | F12: 32 new regression tests in tests/test_validation_fixes.py; 3 skipped need a database not built here
A15: Finding | B15: Severity | C15: Where | D15: What happened | E15: Fix | F15: Status
A16: F1 | B16: Medium | C16: app/cli.py, analyze | D16: Bad case file ended in a traceback (6 of 6 file types) | E16: Same loader and error handling as run | F16: Fixed, tested
A17: F2 | B17: Medium | C17: app/analysis.py | D17: Wrong-type containers crashed (14 of 19 shapes) | E17: Type-check each container, report a case problem | F17: Fixed, tested
A18: F3 | B18: Low | C18: app/analysis.py, decision.py:96 | D18: Mixed-type evidence ids failed when sorted | E18: Convert ids to text | F18: Fixed, tested
A19: F4 | B19: Low | C19: simulation.py, convergence() | D19: Empty checkpoints for n < 10; n = 1 crashed | E19: At least one draw per checkpoint | F19: Fixed, tested
A20: F5 | B20: Low | C20: simulation.py, simulate() | D20: Two ids with equal CRC32 share a random stream | E20: Refuse and ask for a rename (hash unchanged) | F20: Fixed, tested
A21: F6 | B21: Low | C21: examples/example_analysis_case.json | D21: File differed from the generator function | E21: Regenerated; test compares them | F21: Fixed, tested
A22: F7 | B22: Info | C22: app/engine/options.py | D22: Automatic search stops at 3 responses and 40 options | E22: Document in the GUI | F22: Open
A24: Not verified: the PySide6 window and Windows executables (PySide6 not installable here), the browser UI operated by a person, LLM-assisted risk suggestions (no key), line coverage.
A25: Source: report/scripts/validation_2026-10-09/ (first-run and after_fixes outputs). Counts typed from those outputs.
