Workbook

Sheet How it works
A1: How Bricks-ly uses RII values from published research
A4: What an RII is
B5: Relative Importance Index = sum of all ratings / (highest possible rating x number of respondents). Survey respondents rate each delay factor (e.g. 1-5); the RII runs from about 0.2 to 1. A higher RII means respondents judged the factor more important.
B6: An RII is NOT a probability and NOT a number of days of delay. It can only say which risks people consider more important than others.
A8: Where the values come from
B9: Sheet 'Studies' lists 11 published surveys; sheet 'RII_Data' holds every value recorded from them, as printed, with the table and page. Every factor is mapped to a library risk (only 4 unclear or group-level factors are left unmapped).
B10: Seed studies (used by the model): RII surveys from India and Sri Lanka, closest to Indian masonry sites: M01 (India, masonry), A02 (India, masonry), M06 (India), A14 (Sri Lanka), A15 (Sri Lanka).
B11: Validation studies (held out, never used by the model): M10 (Middle East meta-analysis of 10 surveys), M15 (Brazil), M14 (Indonesia, workers), plus A10, A21 and HAS25 with too few overlapping risks to test.
A13: Step by step (sheet 'Seed_Calculation' does this with live formulas)
B14: 1. Map each factor to one of the tool's library risks (38 risks in 11 categories, built from every factor in the studies). Direct = names the same cause (e.g. 'Material shortages' -> R-MAT). Related = overlaps but is broader, narrower or an outcome (e.g. 'Accidents' -> R-SAFE); Related values are shown but not used.
B15: 2. For each risk and seed study, average that study's Direct values, so one study counts once even if it lists two matching factors.
B16: 3. Seed mean RII for the risk = average across the seed studies that have a value.
B17: 4. Rank the seeded risks by seed mean RII and split them into five equal-count bands (with 30 seeded risks, six per band): top band -> class 5, ... bottom band -> class 1. Risks with no seed-study value (for example R-TRN, R-PRD, R-GOV) are not seeded.
B18: 5. In the app, a library risk with no probability or delay entered yet is placed on the 5x5 matrix at (class, class), drawn with a dashed outline and labelled 'literature seed'.
B19: 6. If a site-fact rule flags the risk (e.g. monsoon overlaps the work), its probability class goes up by one, to a maximum of 5.
B20: 7. As soon as the user enters a probability and a delay range (with a Source), the seed is replaced by those numbers.
A22: Worked example: R-WX (rain / monsoon stoppage)
B23: ="Study values: M01 "&TEXT(Seed_Calculation!C11,"0.000")&", A02 "&TEXT(Seed_Calculation!D11,"0.000")&", M06 "&TEXT(Seed_Calculation!E11,"0.000")&", A14 "&TEXT(Seed_Calculation!F11,"0.000") -> Study values: M01 0.764, A02 0.700, M06 0.657, A14 0.653
B24: ="Seed mean RII = "&TEXT(Seed_Calculation!I11,"0.0000")&" -> rank "&Seed_Calculation!J11&" of "&Seed_Calculation!C44&" -> class "&Seed_Calculation!K11&" -> matrix cell "&Seed_Calculation!L11 -> Seed mean RII = 0.6934 -> rank 24 of 30 -> class 2 -> matrix cell p2 × i2
A26: What the validation shows (sheet 'Validation')
B27: Spearman rank correlation between the seed order and each held-out study, over the risks both cover. Read the 'Reading' column; with only 7-9 shared risks, a result must be strong to be statistically significant.
A29: Limits to state in the report
B30: RII is a perception of importance, not a measured frequency or delay. Studies differ in country, project type, respondents (managers vs workers) and rating scale (1-4 vs 1-5). Several values come from research notes rather than a re-read of the PDF (column 'How the values were obtained').
B31: Most seed mean RIIs lie within a few hundredths of each other, so the order of the middle risks is fragile. The seed is a starting point until expert-survey or site data replace it.
A33: Colour key
B34: Blue text = value copied from a paper. Black = formula. Green = formula that pulls from another sheet. Yellow fill = a judgement you may change (study role, factor mapping); the sheets recalculate.
B35: Built by scripts/build_rii_workbook.py from data/literature_seed.json, the same file the app reads. Edit the JSON and rebuild to keep the app and this workbook in step.

Sheet Studies
A1: Studies the RII values come from
A2: Role and the mapping column on RII_Data (yellow) are judgements you may change; everything else is copied from the papers.
A4: ID | B4: Authors | C4: Year | D4: Title | E4: Venue | F4: DOI | G4: Country | H4: Context | I4: Masonry-specific? | J4: Respondents (N) | K4: Rating scale | L4: Where in the paper | M4: How the values were obtained | N4: Role | O4: Note
A5: M01 | B5: Karthik, D. & Rao, C.B.K. | C5: 2019 | D5: The analysis of essential factors responsible for loss of labour productivity in building construction projects in India | E5: Engineering Journal 23(2) | F5: 10.4186/ej.2019.23.2.55 | G5: India (Telangana) | H5: Multi-storey residential building, masonry wall construction | I5: Yes | J5: 44 | K5: 1-5 | L5: Table 3, p.61 | M5: Read from the PDF (Research_Papers/5_Masonry_Productivity_Delay) | N5: Seed | O5: N = 44 from the response counts in Table 3 (each row sums to 44).
A6: A02 | B6: Ponmalar, Aravindraj & Nandhini | C6: 2018 | D6: Study on factors influencing labour productivity in residential buildings in Indian scenario | E6: IJETMR 5(2): 239-248 | F6: 10.29121/ijetmr.v5.i2.2018.168 | G6: India (Chennai) | H6: Two 3-storey residential buildings, brick masonry activity | I6: Yes | J6: Not reported | K6: 1-4 | L6: Tables 1-2 and Fig. 1 | M6: From the research notes (full text read in an earlier session); PDF not in the project folder | N6: Seed | O6: Low-tier journal; respondent count not reported. Payment delays printed as 775.8 on a 1000 scale.
A7: M06 | B7: Dixit, Mandal, Thanikal & Saurabh | C7: 2019 | D7: Study of significant factors affecting construction productivity using relative importance index in Indian construction industry | E7: E3S Web of Conferences 140, 09010 | F7: 10.1051/e3sconf/201914009010 | G7: India | H7: Construction industry (general), consultants, contractors, developers, academia | I7: No | J7: 201 | K7: 1-5 | L7: Table 3, p.5 | M7: Read from the PDF (Research_Papers/5_Masonry_Productivity_Delay) | N7: Seed | O7: RII = total score / (5 x 201). 'Conflict of interest among team members' is printed twice with different values.
A8: A14 | B8: Abeysinghe & Jayathilaka | C8: 2022 | D8: Factors influencing the timely completion of construction projects in Sri Lanka | E8: PLoS ONE 17(12): e0278318 | F8: 10.1371/journal.pone.0278318 | G8: Sri Lanka | H8: Construction projects incl. buildings; clients, contractors, consultants | I8: No | J8: 163 | K8: Not recorded | L8: Table 2 | M8: From the research notes (rows quoted verbatim from the PMC full text) | N8: Seed | O8: Only the rows quoted in the notes are listed (39 factors in the paper).
A9: A15 | B9: Manoharan et al. | C9: 2022 | D9: Labour-related factors affecting construction productivity in Sri Lankan building projects: perspectives of engineers and managers | E9: Frontiers in Engineering and Built Environment | F9: 10.1108/FEBE-03-2022-0009 | G9: Sri Lanka | H9: Building projects, 90 upper-grade contractor firms | I9: No | J9: 90 firms | K9: Not recorded | L9: Top-ranked factors | M9: From the research notes (summary of the full text, two decimals; lower confidence) | N9: Seed | O9: Only the top five factors (of 32) are recorded.
A10: M10 | B10: Adebowale & Agumba | C10: 2023 | D10: A meta-analysis of factors affecting construction labour productivity in the Middle East | E10: Journal of Construction in Developing Countries 28(1): 193-220 | F10: 10.21315/jcdc-12-21-0192 | G10: Middle East (10 studies: Malaysia, Palestine, Kuwait, Qatar, Saudi Arabia, Egypt, Bahrain, Oman, Yemen, Vietnam) | H10: Meta-analysis: pooled RII ('effect summary', random model) of 35 factors | I10: No | J10: 10 studies | K10: Pooled RII | L10: Table 7, pp.210-211 | M10: Read from the PDF (Research_Papers/5_Masonry_Productivity_Delay) | N10: Validation | O10: Rows Man. 20 (delays responding to requests for information, overall rank 1) and Tec. 5 (type of project) were not captured by text extraction; neither maps to a tool risk.
A11: M15 | B11: de Almeida, Feitoza, Carvalho, Pina, Araujo et al. | C11: 2021 | D11: Study of delays in constructions: a managerial point of view of private companies in Brasilia, Brazil | E11: Gestao & Producao 28(3): e5194 | F11: 10.1590/1806-9649-2021v28e5194 | G11: Brazil (Brasilia) | H11: Private building companies; directors, managers, engineers | I11: No | J11: 47 | K11: 1-4 | L11: Table 3, p.8 | M11: Read from the PDF (Research_Papers/5_Masonry_Productivity_Delay) | N11: Validation | O11: RII printed as a percentage; converted to 0-1.
A12: M14 | B12: Loekito, Dani, Zulfikar, Triarso & Prasetyono | C12: 2026 | D12: Factors influencing construction worker productivity in Indonesia and strategies for improvement | E12: Multidisciplinary Science Journal 8: e2026243 | F12: 10.31893/multiscience.2026243 | G12: Indonesia (East Java) | H12: Construction WORKERS' perspective | I12: No | J12: 83 | K12: 1-4 | L12: Table 2, p.5 | M12: Read from the PDF (Research_Papers/5_Masonry_Productivity_Delay) | N12: Validation | O12: Published online 2025. Decimal commas in the PDF converted to points.
A13: A10 | B13: Pinky Devi & Sindhu | C13: 2025 | D13: Delay analysis of infrastructure construction projects in India | E13: Journal of The Institution of Engineers (India): Series A | F13: 10.1007/s40030-025-00899-5 | G13: India | H13: Infrastructure (roads, bridges), NOT buildings | I13: No | J13: 72 | K13: Not recorded | L13: RII table | M13: From the research notes (summary of the full text; lower confidence) | N13: Validation | O13: Only 2 tool risks overlap, too few for a rank correlation. Notes list the group 'material-related issues' as rank 1 although item values are higher; recheck the paper.
A14: A21 | B14: Ouansrimeang & Wisaeang | C14: 2024 | D14: Analyzing the critical delay factors for construction projects in the public sector using relative importance index and machine learning techniques | E14: Journal of Infrastructure, Policy and Development 8(8): 6208 | F14: 10.24294/jipd.v8i8.6208 | G14: Thailand | H14: 30 delayed public projects | I14: No | J14: 30 projects | K14: Not recorded | L14: Results section | M14: From the research notes (full text read) | N14: Validation | O14: Labour issues: 0.773 in the abstract but 0.733 in the results text; 0.733 is used here.
A15: HAS25 | B15: Hassoon et al. | C15: 2025 | D15: (brickwork / housing skeleton tasks, Iraq) | E15: Journal of Infrastructure Preservation and Resilience 6, art. 3 | F15: 10.1186/s43065-025-00116-4 | G15: Iraq | H15: Brickwork and housing skeleton tasks | I15: Yes | J15: Not recorded | K15: Not recorded | L15: Abstract | M15: From the research notes (abstract only) | N15: Validation | O15: Abstract gives only two values. Not in the tool's evidence store.

Sheet RII_Data
A1: Every RII value recorded, one row per factor as printed in the paper
A2: Blue = copied from the paper. Green = looked up from Studies. Black = formula. Yellow = mapping judgement (Direct / Related / blank).
A4: Study ID | B4: Country | C4: Role | D4: Factor (as printed) | E4: RII (0-1) | F4: Rank in study | G4: Tool risk | H4: Mapping | I4: Used by the model? | J4: Note | K4: z-score within study
A5: M01 | B5: =INDEX(Studies!$G$5:$G$15,MATCH(A5,Studies!$A$5:$A$15,0)) -> India (Telangana) | C5: =INDEX(Studies!$N$5:$N$15,MATCH(A5,Studies!$A$5:$A$15,0)) -> Seed | D5: Unsafe working conditions | E5: 0.809 | F5: 1 | G5: R-SAFE | H5: Direct | I5: =IF(AND(C5="Seed",H5="Direct",G5<>""),"Yes","No") -> Yes | K5: =IF(OR(INDEX(Standardised!$B$5:$B$15,MATCH(A5,Standardised!$A$5:$A$15,0))="Complete",INDEX(Standardised!$B$5:$B$15,MATCH(A5,Standardised!$A$5:$A$15,0))="Truncated"),(E5-INDEX(Standardised!$D$5:$D$15,MATCH(A5,Standardised!$A$5:$A$15,0)))/INDEX(Standardised!$E$5:$E$15,MATCH(A5,Standardised!$A$5:$A$15,0)),"") -> 2.2101465
A6: M01 | B6: =INDEX(Studies!$G$5:$G$15,MATCH(A6,Studies!$A$5:$A$15,0)) -> India (Telangana) | C6: =INDEX(Studies!$N$5:$N$15,MATCH(A6,Studies!$A$5:$A$15,0)) -> Seed | D6: Poor work planning | E6: 0.791 | F6: 2 | G6: R-PLAN | H6: Direct | I6: =IF(AND(C6="Seed",H6="Direct",G6<>""),"Yes","No") -> Yes | K6: =IF(OR(INDEX(Standardised!$B$5:$B$15,MATCH(A6,Standardised!$A$5:$A$15,0))="Complete",INDEX(Standardised!$B$5:$B$15,MATCH(A6,Standardised!$A$5:$A$15,0))="Truncated"),(E6-INDEX(Standardised!$D$5:$D$15,MATCH(A6,Standardised!$A$5:$A$15,0)))/INDEX(Standardised!$E$5:$E$15,MATCH(A6,Standardised!$A$5:$A$15,0)),"") -> 1.5552883
A7: M01 | B7: =INDEX(Studies!$G$5:$G$15,MATCH(A7,Studies!$A$5:$A$15,0)) -> India (Telangana) | C7: =INDEX(Studies!$N$5:$N$15,MATCH(A7,Studies!$A$5:$A$15,0)) -> Seed | D7: Unrealistic scheduling | E7: 0.791 | F7: 3 | G7: R-PLAN | H7: Direct | I7: =IF(AND(C7="Seed",H7="Direct",G7<>""),"Yes","No") -> Yes | K7: =IF(OR(INDEX(Standardised!$B$5:$B$15,MATCH(A7,Standardised!$A$5:$A$15,0))="Complete",INDEX(Standardised!$B$5:$B$15,MATCH(A7,Standardised!$A$5:$A$15,0))="Truncated"),(E7-INDEX(Standardised!$D$5:$D$15,MATCH(A7,Standardised!$A$5:$A$15,0)))/INDEX(Standardised!$E$5:$E$15,MATCH(A7,Standardised!$A$5:$A$15,0)),"") -> 1.5552883
A8: M01 | B8: =INDEX(Studies!$G$5:$G$15,MATCH(A8,Studies!$A$5:$A$15,0)) -> India (Telangana) | C8: =INDEX(Studies!$N$5:$N$15,MATCH(A8,Studies!$A$5:$A$15,0)) -> Seed | D8: Little or no financial rewards | E8: 0.777 | F8: 4 | G8: R-INC | H8: Direct | I8: =IF(AND(C8="Seed",H8="Direct",G8<>""),"Yes","No") -> Yes | K8: =IF(OR(INDEX(Standardised!$B$5:$B$15,MATCH(A8,Standardised!$A$5:$A$15,0))="Complete",INDEX(Standardised!$B$5:$B$15,MATCH(A8,Standardised!$A$5:$A$15,0))="Truncated"),(E8-INDEX(Standardised!$D$5:$D$15,MATCH(A8,Standardised!$A$5:$A$15,0)))/INDEX(Standardised!$E$5:$E$15,MATCH(A8,Standardised!$A$5:$A$15,0)),"") -> 1.0459541
A9: M01 | B9: =INDEX(Studies!$G$5:$G$15,MATCH(A9,Studies!$A$5:$A$15,0)) -> India (Telangana) | C9: =INDEX(Studies!$N$5:$N$15,MATCH(A9,Studies!$A$5:$A$15,0)) -> Seed | D9: Material shortages | E9: 0.777 | F9: 5 | G9: R-MAT | H9: Direct | I9: =IF(AND(C9="Seed",H9="Direct",G9<>""),"Yes","No") -> Yes | K9: =IF(OR(INDEX(Standardised!$B$5:$B$15,MATCH(A9,Standardised!$A$5:$A$15,0))="Complete",INDEX(Standardised!$B$5:$B$15,MATCH(A9,Standardised!$A$5:$A$15,0))="Truncated"),(E9-INDEX(Standardised!$D$5:$D$15,MATCH(A9,Standardised!$A$5:$A$15,0)))/INDEX(Standardised!$E$5:$E$15,MATCH(A9,Standardised!$A$5:$A$15,0)),"") -> 1.0459541
A10: M01 | B10: =INDEX(Studies!$G$5:$G$15,MATCH(A10,Studies!$A$5:$A$15,0)) -> India (Telangana) | C10: =INDEX(Studies!$N$5:$N$15,MATCH(A10,Studies!$A$5:$A$15,0)) -> Seed | D10: Payment delay | E10: 0.773 | F10: 6 | G10: R-PAY | H10: Direct | I10: =IF(AND(C10="Seed",H10="Direct",G10<>""),"Yes","No") -> Yes | K10: =IF(OR(INDEX(Standardised!$B$5:$B$15,MATCH(A10,Standardised!$A$5:$A$15,0))="Complete",INDEX(Standardised!$B$5:$B$15,MATCH(A10,Standardised!$A$5:$A$15,0))="Truncated"),(E10-INDEX(Standardised!$D$5:$D$15,MATCH(A10,Standardised!$A$5:$A$15,0)))/INDEX(Standardised!$E$5:$E$15,MATCH(A10,Standardised!$A$5:$A$15,0)),"") -> 0.90043006
A11: M01 | B11: =INDEX(Studies!$G$5:$G$15,MATCH(A11,Studies!$A$5:$A$15,0)) -> India (Telangana) | C11: =INDEX(Studies!$N$5:$N$15,MATCH(A11,Studies!$A$5:$A$15,0)) -> Seed | D11: Working at heights | E11: 0.764 | F11: 7 | G11: R-SAFE | H11: Direct | I11: =IF(AND(C11="Seed",H11="Direct",G11<>""),"Yes","No") -> Yes | K11: =IF(OR(INDEX(Standardised!$B$5:$B$15,MATCH(A11,Standardised!$A$5:$A$15,0))="Complete",INDEX(Standardised!$B$5:$B$15,MATCH(A11,Standardised!$A$5:$A$15,0))="Truncated"),(E11-INDEX(Standardised!$D$5:$D$15,MATCH(A11,Standardised!$A$5:$A$15,0)))/INDEX(Standardised!$E$5:$E$15,MATCH(A11,Standardised!$A$5:$A$15,0)),"") -> 0.57300095
A12: M01 | B12: =INDEX(Studies!$G$5:$G$15,MATCH(A12,Studies!$A$5:$A$15,0)) -> India (Telangana) | C12: =INDEX(Studies!$N$5:$N$15,MATCH(A12,Studies!$A$5:$A$15,0)) -> Seed | D12: Weather conditions | E12: 0.764 | F12: 8 | G12: R-WX | H12: Direct | I12: =IF(AND(C12="Seed",H12="Direct",G12<>""),"Yes","No") -> Yes | K12: =IF(OR(INDEX(Standardised!$B$5:$B$15,MATCH(A12,Standardised!$A$5:$A$15,0))="Complete",INDEX(Standardised!$B$5:$B$15,MATCH(A12,Standardised!$A$5:$A$15,0))="Truncated"),(E12-INDEX(Standardised!$D$5:$D$15,MATCH(A12,Standardised!$A$5:$A$15,0)))/INDEX(Standardised!$E$5:$E$15,MATCH(A12,Standardised!$A$5:$A$15,0)),"") -> 0.57300095
A13: M01 | B13: =INDEX(Studies!$G$5:$G$15,MATCH(A13,Studies!$A$5:$A$15,0)) -> India (Telangana) | C13: =INDEX(Studies!$N$5:$N$15,MATCH(A13,Studies!$A$5:$A$15,0)) -> Seed | D13: Lack of skill and experience of worker | E13: 0.759 | F13: 9 | G13: R-SKILL | H13: Direct | I13: =IF(AND(C13="Seed",H13="Direct",G13<>""),"Yes","No") -> Yes | K13: =IF(OR(INDEX(Standardised!$B$5:$B$15,MATCH(A13,Standardised!$A$5:$A$15,0))="Complete",INDEX(Standardised!$B$5:$B$15,MATCH(A13,Standardised!$A$5:$A$15,0))="Truncated"),(E13-INDEX(Standardised!$D$5:$D$15,MATCH(A13,Standardised!$A$5:$A$15,0)))/INDEX(Standardised!$E$5:$E$15,MATCH(A13,Standardised!$A$5:$A$15,0)),"") -> 0.39109588
A14: M01 | B14: =INDEX(Studies!$G$5:$G$15,MATCH(A14,Studies!$A$5:$A$15,0)) -> India (Telangana) | C14: =INDEX(Studies!$N$5:$N$15,MATCH(A14,Studies!$A$5:$A$15,0)) -> Seed | D14: Poor or no supervision method | E14: 0.759 | F14: 10 | G14: R-SUP | H14: Direct | I14: =IF(AND(C14="Seed",H14="Direct",G14<>""),"Yes","No") -> Yes | K14: =IF(OR(INDEX(Standardised!$B$5:$B$15,MATCH(A14,Standardised!$A$5:$A$15,0))="Complete",INDEX(Standardised!$B$5:$B$15,MATCH(A14,Standardised!$A$5:$A$15,0))="Truncated"),(E14-INDEX(Standardised!$D$5:$D$15,MATCH(A14,Standardised!$A$5:$A$15,0)))/INDEX(Standardised!$E$5:$E$15,MATCH(A14,Standardised!$A$5:$A$15,0)),"") -> 0.39109588
A15: M01 | B15: =INDEX(Studies!$G$5:$G$15,MATCH(A15,Studies!$A$5:$A$15,0)) -> India (Telangana) | C15: =INDEX(Studies!$N$5:$N$15,MATCH(A15,Studies!$A$5:$A$15,0)) -> Seed | D15: Incompetent supervisors | E15: 0.759 | F15: 11 | G15: R-SUP | H15: Direct | I15: =IF(AND(C15="Seed",H15="Direct",G15<>""),"Yes","No") -> Yes | K15: =IF(OR(INDEX(Standardised!$B$5:$B$15,MATCH(A15,Standardised!$A$5:$A$15,0))="Complete",INDEX(Standardised!$B$5:$B$15,MATCH(A15,Standardised!$A$5:$A$15,0))="Truncated"),(E15-INDEX(Standardised!$D$5:$D$15,MATCH(A15,Standardised!$A$5:$A$15,0)))/INDEX(Standardised!$E$5:$E$15,MATCH(A15,Standardised!$A$5:$A$15,0)),"") -> 0.39109588
A16: M01 | B16: =INDEX(Studies!$G$5:$G$15,MATCH(A16,Studies!$A$5:$A$15,0)) -> India (Telangana) | C16: =INDEX(Studies!$N$5:$N$15,MATCH(A16,Studies!$A$5:$A$15,0)) -> Seed | D16: Accidents | E16: 0.759 | F16: 12 | G16: R-ACC | H16: Direct | I16: =IF(AND(C16="Seed",H16="Direct",G16<>""),"Yes","No") -> Yes | J16: an outcome of unsafe conditions, not the condition itself | K16: =IF(OR(INDEX(Standardised!$B$5:$B$15,MATCH(A16,Standardised!$A$5:$A$15,0))="Complete",INDEX(Standardised!$B$5:$B$15,MATCH(A16,Standardised!$A$5:$A$15,0))="Truncated"),(E16-INDEX(Standardised!$D$5:$D$15,MATCH(A16,Standardised!$A$5:$A$15,0)))/INDEX(Standardised!$E$5:$E$15,MATCH(A16,Standardised!$A$5:$A$15,0)),"") -> 0.39109588
A17: M01 | B17: =INDEX(Studies!$G$5:$G$15,MATCH(A17,Studies!$A$5:$A$15,0)) -> India (Telangana) | C17: =INDEX(Studies!$N$5:$N$15,MATCH(A17,Studies!$A$5:$A$15,0)) -> Seed | D17: Poor relation between labour and superintendents | E17: 0.755 | F17: 13 | G17: R-COM | H17: Related | I17: =IF(AND(C17="Seed",H17="Direct",G17<>""),"Yes","No") -> No | K17: =IF(OR(INDEX(Standardised!$B$5:$B$15,MATCH(A17,Standardised!$A$5:$A$15,0))="Complete",INDEX(Standardised!$B$5:$B$15,MATCH(A17,Standardised!$A$5:$A$15,0))="Truncated"),(E17-INDEX(Standardised!$D$5:$D$15,MATCH(A17,Standardised!$A$5:$A$15,0)))/INDEX(Standardised!$E$5:$E$15,MATCH(A17,Standardised!$A$5:$A$15,0)),"") -> 0.24557183
A18: M01 | B18: =INDEX(Studies!$G$5:$G$15,MATCH(A18,Studies!$A$5:$A$15,0)) -> India (Telangana) | C18: =INDEX(Studies!$N$5:$N$15,MATCH(A18,Studies!$A$5:$A$15,0)) -> Seed | D18: Poor condition of equipment and tools | E18: 0.75 | F18: 14 | G18: R-TOOL | H18: Direct | I18: =IF(AND(C18="Seed",H18="Direct",G18<>""),"Yes","No") -> Yes | K18: =IF(OR(INDEX(Standardised!$B$5:$B$15,MATCH(A18,Standardised!$A$5:$A$15,0))="Complete",INDEX(Standardised!$B$5:$B$15,MATCH(A18,Standardised!$A$5:$A$15,0))="Truncated"),(E18-INDEX(Standardised!$D$5:$D$15,MATCH(A18,Standardised!$A$5:$A$15,0)))/INDEX(Standardised!$E$5:$E$15,MATCH(A18,Standardised!$A$5:$A$15,0)),"") -> 0.063666772
A19: M01 | B19: =INDEX(Studies!$G$5:$G$15,MATCH(A19,Studies!$A$5:$A$15,0)) -> India (Telangana) | C19: =INDEX(Studies!$N$5:$N$15,MATCH(A19,Studies!$A$5:$A$15,0)) -> Seed | D19: Bad leadership skill | E19: 0.75 | F19: 15 | G19: R-DIS | H19: Direct | I19: =IF(AND(C19="Seed",H19="Direct",G19<>""),"Yes","No") -> Yes | K19: =IF(OR(INDEX(Standardised!$B$5:$B$15,MATCH(A19,Standardised!$A$5:$A$15,0))="Complete",INDEX(Standardised!$B$5:$B$15,MATCH(A19,Standardised!$A$5:$A$15,0))="Truncated"),(E19-INDEX(Standardised!$D$5:$D$15,MATCH(A19,Standardised!$A$5:$A$15,0)))/INDEX(Standardised!$E$5:$E$15,MATCH(A19,Standardised!$A$5:$A$15,0)),"") -> 0.063666772
A20: M01 | B20: =INDEX(Studies!$G$5:$G$15,MATCH(A20,Studies!$A$5:$A$15,0)) -> India (Telangana) | C20: =INDEX(Studies!$N$5:$N$15,MATCH(A20,Studies!$A$5:$A$15,0)) -> Seed | D20: Working 7 days per week | E20: 0.741 | F20: 16 | G20: R-OVT | H20: Direct | I20: =IF(AND(C20="Seed",H20="Direct",G20<>""),"Yes","No") -> Yes | K20: =IF(OR(INDEX(Standardised!$B$5:$B$15,MATCH(A20,Standardised!$A$5:$A$15,0))="Complete",INDEX(Standardised!$B$5:$B$15,MATCH(A20,Standardised!$A$5:$A$15,0))="Truncated"),(E20-INDEX(Standardised!$D$5:$D$15,MATCH(A20,Standardised!$A$5:$A$15,0)))/INDEX(Standardised!$E$5:$E$15,MATCH(A20,Standardised!$A$5:$A$15,0)),"") -> -0.26376234
A21: M01 | B21: =INDEX(Studies!$G$5:$G$15,MATCH(A21,Studies!$A$5:$A$15,0)) -> India (Telangana) | C21: =INDEX(Studies!$N$5:$N$15,MATCH(A21,Studies!$A$5:$A$15,0)) -> Seed | D21: Equipment and tools shortages | E21: 0.741 | F21: 17 | G21: R-TOOL | H21: Direct | I21: =IF(AND(C21="Seed",H21="Direct",G21<>""),"Yes","No") -> Yes | K21: =IF(OR(INDEX(Standardised!$B$5:$B$15,MATCH(A21,Standardised!$A$5:$A$15,0))="Complete",INDEX(Standardised!$B$5:$B$15,MATCH(A21,Standardised!$A$5:$A$15,0))="Truncated"),(E21-INDEX(Standardised!$D$5:$D$15,MATCH(A21,Standardised!$A$5:$A$15,0)))/INDEX(Standardised!$E$5:$E$15,MATCH(A21,Standardised!$A$5:$A$15,0)),"") -> -0.26376234
A22: M01 | B22: =INDEX(Studies!$G$5:$G$15,MATCH(A22,Studies!$A$5:$A$15,0)) -> India (Telangana) | C22: =INDEX(Studies!$N$5:$N$15,MATCH(A22,Studies!$A$5:$A$15,0)) -> Seed | D22: Low labour morale/commitment | E22: 0.736 | F22: 18 | G22: R-MOT | H22: Direct | I22: =IF(AND(C22="Seed",H22="Direct",G22<>""),"Yes","No") -> Yes | K22: =IF(OR(INDEX(Standardised!$B$5:$B$15,MATCH(A22,Standardised!$A$5:$A$15,0))="Complete",INDEX(Standardised!$B$5:$B$15,MATCH(A22,Standardised!$A$5:$A$15,0))="Truncated"),(E22-INDEX(Standardised!$D$5:$D$15,MATCH(A22,Standardised!$A$5:$A$15,0)))/INDEX(Standardised!$E$5:$E$15,MATCH(A22,Standardised!$A$5:$A$15,0)),"") -> -0.4456674
A23: M01 | B23: =INDEX(Studies!$G$5:$G$15,MATCH(A23,Studies!$A$5:$A$15,0)) -> India (Telangana) | C23: =INDEX(Studies!$N$5:$N$15,MATCH(A23,Studies!$A$5:$A$15,0)) -> Seed | D23: Rework | E23: 0.736 | F23: 19 | G23: R-RWK | H23: Direct | I23: =IF(AND(C23="Seed",H23="Direct",G23<>""),"Yes","No") -> Yes | K23: =IF(OR(INDEX(Standardised!$B$5:$B$15,MATCH(A23,Standardised!$A$5:$A$15,0))="Complete",INDEX(Standardised!$B$5:$B$15,MATCH(A23,Standardised!$A$5:$A$15,0))="Truncated"),(E23-INDEX(Standardised!$D$5:$D$15,MATCH(A23,Standardised!$A$5:$A$15,0)))/INDEX(Standardised!$E$5:$E$15,MATCH(A23,Standardised!$A$5:$A$15,0)),"") -> -0.4456674
A24: M01 | B24: =INDEX(Studies!$G$5:$G$15,MATCH(A24,Studies!$A$5:$A$15,0)) -> India (Telangana) | C24: =INDEX(Studies!$N$5:$N$15,MATCH(A24,Studies!$A$5:$A$15,0)) -> Seed | D24: Lack of empowerment | E24: 0.732 | F24: 20 | G24: R-MOT | H24: Related | I24: =IF(AND(C24="Seed",H24="Direct",G24<>""),"Yes","No") -> No | K24: =IF(OR(INDEX(Standardised!$B$5:$B$15,MATCH(A24,Standardised!$A$5:$A$15,0))="Complete",INDEX(Standardised!$B$5:$B$15,MATCH(A24,Standardised!$A$5:$A$15,0))="Truncated"),(E24-INDEX(Standardised!$D$5:$D$15,MATCH(A24,Standardised!$A$5:$A$15,0)))/INDEX(Standardised!$E$5:$E$15,MATCH(A24,Standardised!$A$5:$A$15,0)),"") -> -0.59119145
A25: M01 | B25: =INDEX(Studies!$G$5:$G$15,MATCH(A25,Studies!$A$5:$A$15,0)) -> India (Telangana) | C25: =INDEX(Studies!$N$5:$N$15,MATCH(A25,Studies!$A$5:$A$15,0)) -> Seed | D25: Change order during execution | E25: 0.732 | F25: 21 | G25: R-DES | H25: Direct | I25: =IF(AND(C25="Seed",H25="Direct",G25<>""),"Yes","No") -> Yes | K25: =IF(OR(INDEX(Standardised!$B$5:$B$15,MATCH(A25,Standardised!$A$5:$A$15,0))="Complete",INDEX(Standardised!$B$5:$B$15,MATCH(A25,Standardised!$A$5:$A$15,0))="Truncated"),(E25-INDEX(Standardised!$D$5:$D$15,MATCH(A25,Standardised!$A$5:$A$15,0)))/INDEX(Standardised!$E$5:$E$15,MATCH(A25,Standardised!$A$5:$A$15,0)),"") -> -0.59119145
A26: M01 | B26: =INDEX(Studies!$G$5:$G$15,MATCH(A26,Studies!$A$5:$A$15,0)) -> India (Telangana) | C26: =INDEX(Studies!$N$5:$N$15,MATCH(A26,Studies!$A$5:$A$15,0)) -> Seed | D26: Low amount of pay | E26: 0.727 | F26: 22 | G26: R-INC | H26: Direct | I26: =IF(AND(C26="Seed",H26="Direct",G26<>""),"Yes","No") -> Yes | K26: =IF(OR(INDEX(Standardised!$B$5:$B$15,MATCH(A26,Standardised!$A$5:$A$15,0))="Complete",INDEX(Standardised!$B$5:$B$15,MATCH(A26,Standardised!$A$5:$A$15,0))="Truncated"),(E26-INDEX(Standardised!$D$5:$D$15,MATCH(A26,Standardised!$A$5:$A$15,0)))/INDEX(Standardised!$E$5:$E$15,MATCH(A26,Standardised!$A$5:$A$15,0)),"") -> -0.77309652
A27: M01 | B27: =INDEX(Studies!$G$5:$G$15,MATCH(A27,Studies!$A$5:$A$15,0)) -> India (Telangana) | C27: =INDEX(Studies!$N$5:$N$15,MATCH(A27,Studies!$A$5:$A$15,0)) -> Seed | D27: High workforce absenteeism | E27: 0.723 | F27: 23 | G27: R-LAB | H27: Direct | I27: =IF(AND(C27="Seed",H27="Direct",G27<>""),"Yes","No") -> Yes | K27: =IF(OR(INDEX(Standardised!$B$5:$B$15,MATCH(A27,Standardised!$A$5:$A$15,0))="Complete",INDEX(Standardised!$B$5:$B$15,MATCH(A27,Standardised!$A$5:$A$15,0))="Truncated"),(E27-INDEX(Standardised!$D$5:$D$15,MATCH(A27,Standardised!$A$5:$A$15,0)))/INDEX(Standardised!$E$5:$E$15,MATCH(A27,Standardised!$A$5:$A$15,0)),"") -> -0.91862057
A28: M01 | B28: =INDEX(Studies!$G$5:$G$15,MATCH(A28,Studies!$A$5:$A$15,0)) -> India (Telangana) | C28: =INDEX(Studies!$N$5:$N$15,MATCH(A28,Studies!$A$5:$A$15,0)) -> Seed | D28: Lack of labour surveillance | E28: 0.714 | F28: 24 | G28: R-SUP | H28: Direct | I28: =IF(AND(C28="Seed",H28="Direct",G28<>""),"Yes","No") -> Yes | K28: =IF(OR(INDEX(Standardised!$B$5:$B$15,MATCH(A28,Standardised!$A$5:$A$15,0))="Complete",INDEX(Standardised!$B$5:$B$15,MATCH(A28,Standardised!$A$5:$A$15,0))="Truncated"),(E28-INDEX(Standardised!$D$5:$D$15,MATCH(A28,Standardised!$A$5:$A$15,0)))/INDEX(Standardised!$E$5:$E$15,MATCH(A28,Standardised!$A$5:$A$15,0)),"") -> -1.2460497
A29: M01 | B29: =INDEX(Studies!$G$5:$G$15,MATCH(A29,Studies!$A$5:$A$15,0)) -> India (Telangana) | C29: =INDEX(Studies!$N$5:$N$15,MATCH(A29,Studies!$A$5:$A$15,0)) -> Seed | D29: Inadequate safety plan | E29: 0.714 | F29: 25 | G29: R-SAFE | H29: Related | I29: =IF(AND(C29="Seed",H29="Direct",G29<>""),"Yes","No") -> No | J29: a management cause, broader than the site condition | K29: =IF(OR(INDEX(Standardised!$B$5:$B$15,MATCH(A29,Standardised!$A$5:$A$15,0))="Complete",INDEX(Standardised!$B$5:$B$15,MATCH(A29,Standardised!$A$5:$A$15,0))="Truncated"),(E29-INDEX(Standardised!$D$5:$D$15,MATCH(A29,Standardised!$A$5:$A$15,0)))/INDEX(Standardised!$E$5:$E$15,MATCH(A29,Standardised!$A$5:$A$15,0)),"") -> -1.2460497
A30: M01 | B30: =INDEX(Studies!$G$5:$G$15,MATCH(A30,Studies!$A$5:$A$15,0)) -> India (Telangana) | C30: =INDEX(Studies!$N$5:$N$15,MATCH(A30,Studies!$A$5:$A$15,0)) -> Seed | D30: Frequency of working overtime | E30: 0.709 | F30: 26 | G30: R-OVT | H30: Direct | I30: =IF(AND(C30="Seed",H30="Direct",G30<>""),"Yes","No") -> Yes | K30: =IF(OR(INDEX(Standardised!$B$5:$B$15,MATCH(A30,Standardised!$A$5:$A$15,0))="Complete",INDEX(Standardised!$B$5:$B$15,MATCH(A30,Standardised!$A$5:$A$15,0))="Truncated"),(E30-INDEX(Standardised!$D$5:$D$15,MATCH(A30,Standardised!$A$5:$A$15,0)))/INDEX(Standardised!$E$5:$E$15,MATCH(A30,Standardised!$A$5:$A$15,0)),"") -> -1.4279547
A31: M01 | B31: =INDEX(Studies!$G$5:$G$15,MATCH(A31,Studies!$A$5:$A$15,0)) -> India (Telangana) | C31: =INDEX(Studies!$N$5:$N$15,MATCH(A31,Studies!$A$5:$A$15,0)) -> Seed | D31: Effectiveness of management system | E31: 0.709 | F31: 27 | G31: R-MGT | H31: Direct | I31: =IF(AND(C31="Seed",H31="Direct",G31<>""),"Yes","No") -> Yes | K31: =IF(OR(INDEX(Standardised!$B$5:$B$15,MATCH(A31,Standardised!$A$5:$A$15,0))="Complete",INDEX(Standardised!$B$5:$B$15,MATCH(A31,Standardised!$A$5:$A$15,0))="Truncated"),(E31-INDEX(Standardised!$D$5:$D$15,MATCH(A31,Standardised!$A$5:$A$15,0)))/INDEX(Standardised!$E$5:$E$15,MATCH(A31,Standardised!$A$5:$A$15,0)),"") -> -1.4279547
A32: M01 | B32: =INDEX(Studies!$G$5:$G$15,MATCH(A32,Studies!$A$5:$A$15,0)) -> India (Telangana) | C32: =INDEX(Studies!$N$5:$N$15,MATCH(A32,Studies!$A$5:$A$15,0)) -> Seed | D32: Method of construction | E32: 0.7 | F32: 28 | G32: R-MTH | H32: Direct | I32: =IF(AND(C32="Seed",H32="Direct",G32<>""),"Yes","No") -> Yes | K32: =IF(OR(INDEX(Standardised!$B$5:$B$15,MATCH(A32,Standardised!$A$5:$A$15,0))="Complete",INDEX(Standardised!$B$5:$B$15,MATCH(A32,Standardised!$A$5:$A$15,0))="Truncated"),(E32-INDEX(Standardised!$D$5:$D$15,MATCH(A32,Standardised!$A$5:$A$15,0)))/INDEX(Standardised!$E$5:$E$15,MATCH(A32,Standardised!$A$5:$A$15,0)),"") -> -1.7553839
A33: A02 | B33: =INDEX(Studies!$G$5:$G$15,MATCH(A33,Studies!$A$5:$A$15,0)) -> India (Chennai) | C33: =INDEX(Studies!$N$5:$N$15,MATCH(A33,Studies!$A$5:$A$15,0)) -> Seed | D33: Lack of experience (manpower) | E33: 0.787 | F33: 1 | G33: R-SKILL | H33: Direct | I33: =IF(AND(C33="Seed",H33="Direct",G33<>""),"Yes","No") -> Yes | J33: rank within Table 1 (manpower) | K33: =IF(OR(INDEX(Standardised!$B$5:$B$15,MATCH(A33,Standardised!$A$5:$A$15,0))="Complete",INDEX(Standardised!$B$5:$B$15,MATCH(A33,Standardised!$A$5:$A$15,0))="Truncated"),(E33-INDEX(Standardised!$D$5:$D$15,MATCH(A33,Standardised!$A$5:$A$15,0)))/INDEX(Standardised!$E$5:$E$15,MATCH(A33,Standardised!$A$5:$A$15,0)),"")
A34: A02 | B34: =INDEX(Studies!$G$5:$G$15,MATCH(A34,Studies!$A$5:$A$15,0)) -> India (Chennai) | C34: =INDEX(Studies!$N$5:$N$15,MATCH(A34,Studies!$A$5:$A$15,0)) -> Seed | D34: Absenteeism | E34: 0.751 | F34: 2 | G34: R-LAB | H34: Direct | I34: =IF(AND(C34="Seed",H34="Direct",G34<>""),"Yes","No") -> Yes | J34: rank within Table 1 (manpower) | K34: =IF(OR(INDEX(Standardised!$B$5:$B$15,MATCH(A34,Standardised!$A$5:$A$15,0))="Complete",INDEX(Standardised!$B$5:$B$15,MATCH(A34,Standardised!$A$5:$A$15,0))="Truncated"),(E34-INDEX(Standardised!$D$5:$D$15,MATCH(A34,Standardised!$A$5:$A$15,0)))/INDEX(Standardised!$E$5:$E$15,MATCH(A34,Standardised!$A$5:$A$15,0)),"")
A35: A02 | B35: =INDEX(Studies!$G$5:$G$15,MATCH(A35,Studies!$A$5:$A$15,0)) -> India (Chennai) | C35: =INDEX(Studies!$N$5:$N$15,MATCH(A35,Studies!$A$5:$A$15,0)) -> Seed | D35: Age | E35: 0.73 | G35: R-FAT | H35: Related | I35: =IF(AND(C35="Seed",H35="Direct",G35<>""),"Yes","No") -> No | J35: Table 1 (manpower) | K35: =IF(OR(INDEX(Standardised!$B$5:$B$15,MATCH(A35,Standardised!$A$5:$A$15,0))="Complete",INDEX(Standardised!$B$5:$B$15,MATCH(A35,Standardised!$A$5:$A$15,0))="Truncated"),(E35-INDEX(Standardised!$D$5:$D$15,MATCH(A35,Standardised!$A$5:$A$15,0)))/INDEX(Standardised!$E$5:$E$15,MATCH(A35,Standardised!$A$5:$A$15,0)),"")
A36: A02 | B36: =INDEX(Studies!$G$5:$G$15,MATCH(A36,Studies!$A$5:$A$15,0)) -> India (Chennai) | C36: =INDEX(Studies!$N$5:$N$15,MATCH(A36,Studies!$A$5:$A$15,0)) -> Seed | D36: Misunderstanding among labourers | E36: 0.68 | G36: R-COM | H36: Direct | I36: =IF(AND(C36="Seed",H36="Direct",G36<>""),"Yes","No") -> Yes | J36: Table 1 (manpower) | K36: =IF(OR(INDEX(Standardised!$B$5:$B$15,MATCH(A36,Standardised!$A$5:$A$15,0))="Complete",INDEX(Standardised!$B$5:$B$15,MATCH(A36,Standardised!$A$5:$A$15,0))="Truncated"),(E36-INDEX(Standardised!$D$5:$D$15,MATCH(A36,Standardised!$A$5:$A$15,0)))/INDEX(Standardised!$E$5:$E$15,MATCH(A36,Standardised!$A$5:$A$15,0)),"")
A37: A02 | B37: =INDEX(Studies!$G$5:$G$15,MATCH(A37,Studies!$A$5:$A$15,0)) -> India (Chennai) | C37: =INDEX(Studies!$N$5:$N$15,MATCH(A37,Studies!$A$5:$A$15,0)) -> Seed | D37: Accidents | E37: 0.65 | G37: R-ACC | H37: Direct | I37: =IF(AND(C37="Seed",H37="Direct",G37<>""),"Yes","No") -> Yes | J37: Table 1; an outcome, not the condition | K37: =IF(OR(INDEX(Standardised!$B$5:$B$15,MATCH(A37,Standardised!$A$5:$A$15,0))="Complete",INDEX(Standardised!$B$5:$B$15,MATCH(A37,Standardised!$A$5:$A$15,0))="Truncated"),(E37-INDEX(Standardised!$D$5:$D$15,MATCH(A37,Standardised!$A$5:$A$15,0)))/INDEX(Standardised!$E$5:$E$15,MATCH(A37,Standardised!$A$5:$A$15,0)),"")
A38: A02 | B38: =INDEX(Studies!$G$5:$G$15,MATCH(A38,Studies!$A$5:$A$15,0)) -> India (Chennai) | C38: =INDEX(Studies!$N$5:$N$15,MATCH(A38,Studies!$A$5:$A$15,0)) -> Seed | D38: Personal problems | E38: 0.61 | G38: R-FAT | H38: Direct | I38: =IF(AND(C38="Seed",H38="Direct",G38<>""),"Yes","No") -> Yes | J38: Table 1 (manpower) | K38: =IF(OR(INDEX(Standardised!$B$5:$B$15,MATCH(A38,Standardised!$A$5:$A$15,0))="Complete",INDEX(Standardised!$B$5:$B$15,MATCH(A38,Standardised!$A$5:$A$15,0))="Truncated"),(E38-INDEX(Standardised!$D$5:$D$15,MATCH(A38,Standardised!$A$5:$A$15,0)))/INDEX(Standardised!$E$5:$E$15,MATCH(A38,Standardised!$A$5:$A$15,0)),"")
A39: A02 | B39: =INDEX(Studies!$G$5:$G$15,MATCH(A39,Studies!$A$5:$A$15,0)) -> India (Chennai) | C39: =INDEX(Studies!$N$5:$N$15,MATCH(A39,Studies!$A$5:$A$15,0)) -> Seed | D39: Lack of required construction material | E39: 0.78 | F39: 1 | G39: R-MAT | H39: Direct | I39: =IF(AND(C39="Seed",H39="Direct",G39<>""),"Yes","No") -> Yes | J39: rank within Table 2 (resources) | K39: =IF(OR(INDEX(Standardised!$B$5:$B$15,MATCH(A39,Standardised!$A$5:$A$15,0))="Complete",INDEX(Standardised!$B$5:$B$15,MATCH(A39,Standardised!$A$5:$A$15,0))="Truncated"),(E39-INDEX(Standardised!$D$5:$D$15,MATCH(A39,Standardised!$A$5:$A$15,0)))/INDEX(Standardised!$E$5:$E$15,MATCH(A39,Standardised!$A$5:$A$15,0)),"")
A40: A02 | B40: =INDEX(Studies!$G$5:$G$15,MATCH(A40,Studies!$A$5:$A$15,0)) -> India (Chennai) | C40: =INDEX(Studies!$N$5:$N$15,MATCH(A40,Studies!$A$5:$A$15,0)) -> Seed | D40: Lack of tools/equipment | E40: 0.76 | G40: R-TOOL | H40: Direct | I40: =IF(AND(C40="Seed",H40="Direct",G40<>""),"Yes","No") -> Yes | J40: Table 2 (resources) | K40: =IF(OR(INDEX(Standardised!$B$5:$B$15,MATCH(A40,Standardised!$A$5:$A$15,0))="Complete",INDEX(Standardised!$B$5:$B$15,MATCH(A40,Standardised!$A$5:$A$15,0))="Truncated"),(E40-INDEX(Standardised!$D$5:$D$15,MATCH(A40,Standardised!$A$5:$A$15,0)))/INDEX(Standardised!$E$5:$E$15,MATCH(A40,Standardised!$A$5:$A$15,0)),"")
A41: A02 | B41: =INDEX(Studies!$G$5:$G$15,MATCH(A41,Studies!$A$5:$A$15,0)) -> India (Chennai) | C41: =INDEX(Studies!$N$5:$N$15,MATCH(A41,Studies!$A$5:$A$15,0)) -> Seed | D41: Poor site condition | E41: 0.751 | G41: R-SITE | H41: Direct | I41: =IF(AND(C41="Seed",H41="Direct",G41<>""),"Yes","No") -> Yes | J41: Table 2 (resources) | K41: =IF(OR(INDEX(Standardised!$B$5:$B$15,MATCH(A41,Standardised!$A$5:$A$15,0))="Complete",INDEX(Standardised!$B$5:$B$15,MATCH(A41,Standardised!$A$5:$A$15,0))="Truncated"),(E41-INDEX(Standardised!$D$5:$D$15,MATCH(A41,Standardised!$A$5:$A$15,0)))/INDEX(Standardised!$E$5:$E$15,MATCH(A41,Standardised!$A$5:$A$15,0)),"")
...

Sheet Seed_Calculation
A1: Literature seed: how the model turns RII values into a place on the risk matrix
A2: Each study cell = average of that study's DIRECT values for the risk. Seed mean = average across studies. Rank -> five equal bands -> class.
A4: Risk ID | B4: Risk | C4: M01 | D4: A02 | E4: M06 | F4: A14 | G4: A15 | H4: Studies with a value | I4: Seed mean RII | J4: Rank | K4: Class (1-5) | L4: Matrix cell (p × impact) | M4: Level
A5: R-MAT | B5: Brick / block / mortar material shortage or late delivery | C5: =IFERROR(AVERAGEIFS(RII_Data!$E$5:$E$186,RII_Data!$A$5:$A$186,C$4,RII_Data!$G$5:$G$186,$A5,RII_Data!$H$5:$H$186,"Direct",RII_Data!$C$5:$C$186,"Seed"),"") -> 0.777 | D5: =IFERROR(AVERAGEIFS(RII_Data!$E$5:$E$186,RII_Data!$A$5:$A$186,D$4,RII_Data!$G$5:$G$186,$A5,RII_Data!$H$5:$H$186,"Direct",RII_Data!$C$5:$C$186,"Seed"),"") -> 0.78 | E5: =IFERROR(AVERAGEIFS(RII_Data!$E$5:$E$186,RII_Data!$A$5:$A$186,E$4,RII_Data!$G$5:$G$186,$A5,RII_Data!$H$5:$H$186,"Direct",RII_Data!$C$5:$C$186,"Seed"),"") | F5: =IFERROR(AVERAGEIFS(RII_Data!$E$5:$E$186,RII_Data!$A$5:$A$186,F$4,RII_Data!$G$5:$G$186,$A5,RII_Data!$H$5:$H$186,"Direct",RII_Data!$C$5:$C$186,"Seed"),"") -> 0.8098 | G5: =IFERROR(AVERAGEIFS(RII_Data!$E$5:$E$186,RII_Data!$A$5:$A$186,G$4,RII_Data!$G$5:$G$186,$A5,RII_Data!$H$5:$H$186,"Direct",RII_Data!$C$5:$C$186,"Seed"),"") | H5: =COUNT(C5:G5) -> 3 | I5: =IF(H5=0,"",AVERAGE(C5:G5)) -> 0.78893333 | J5: =IF(I5="","",RANK(I5,$I$5:$I$42,0)+COUNTIFS($I$5:$I$42,I5,$A$5:$A$42,"<"&$A5)) -> 1 | K5: =IF(J5="","",5-INT((J5-1)*5/$C$44)) -> 5 | L5: =IF(K5="","not seeded","p"&K5&" × i"&K5) -> p5 × i5 | M5: =IF(K5="","",IF(K5^2<=5,"Low",IF(K5^2<=10,"Moderate",IF(K5^2<=15,"High","Extreme")))) -> Extreme
A6: R-TOOL | B6: Tools and equipment delay | C6: =IFERROR(AVERAGEIFS(RII_Data!$E$5:$E$186,RII_Data!$A$5:$A$186,C$4,RII_Data!$G$5:$G$186,$A6,RII_Data!$H$5:$H$186,"Direct",RII_Data!$C$5:$C$186,"Seed"),"") -> 0.7455 | D6: =IFERROR(AVERAGEIFS(RII_Data!$E$5:$E$186,RII_Data!$A$5:$A$186,D$4,RII_Data!$G$5:$G$186,$A6,RII_Data!$H$5:$H$186,"Direct",RII_Data!$C$5:$C$186,"Seed"),"") -> 0.76 | E6: =IFERROR(AVERAGEIFS(RII_Data!$E$5:$E$186,RII_Data!$A$5:$A$186,E$4,RII_Data!$G$5:$G$186,$A6,RII_Data!$H$5:$H$186,"Direct",RII_Data!$C$5:$C$186,"Seed"),"") | F6: =IFERROR(AVERAGEIFS(RII_Data!$E$5:$E$186,RII_Data!$A$5:$A$186,F$4,RII_Data!$G$5:$G$186,$A6,RII_Data!$H$5:$H$186,"Direct",RII_Data!$C$5:$C$186,"Seed"),"") | G6: =IFERROR(AVERAGEIFS(RII_Data!$E$5:$E$186,RII_Data!$A$5:$A$186,G$4,RII_Data!$G$5:$G$186,$A6,RII_Data!$H$5:$H$186,"Direct",RII_Data!$C$5:$C$186,"Seed"),"") | H6: =COUNT(C6:G6) -> 2 | I6: =IF(H6=0,"",AVERAGE(C6:G6)) -> 0.75275 | J6: =IF(I6="","",RANK(I6,$I$5:$I$42,0)+COUNTIFS($I$5:$I$42,I6,$A$5:$A$42,"<"&$A6)) -> 12 | K6: =IF(J6="","",5-INT((J6-1)*5/$C$44)) -> 4 | L6: =IF(K6="","not seeded","p"&K6&" × i"&K6) -> p4 × i4 | M6: =IF(K6="","",IF(K6^2<=5,"Low",IF(K6^2<=10,"Moderate",IF(K6^2<=15,"High","Extreme")))) -> Extreme
A7: R-LAB | B7: Labour absenteeism or shortage | C7: =IFERROR(AVERAGEIFS(RII_Data!$E$5:$E$186,RII_Data!$A$5:$A$186,C$4,RII_Data!$G$5:$G$186,$A7,RII_Data!$H$5:$H$186,"Direct",RII_Data!$C$5:$C$186,"Seed"),"") -> 0.723 | D7: =IFERROR(AVERAGEIFS(RII_Data!$E$5:$E$186,RII_Data!$A$5:$A$186,D$4,RII_Data!$G$5:$G$186,$A7,RII_Data!$H$5:$H$186,"Direct",RII_Data!$C$5:$C$186,"Seed"),"") -> 0.751 | E7: =IFERROR(AVERAGEIFS(RII_Data!$E$5:$E$186,RII_Data!$A$5:$A$186,E$4,RII_Data!$G$5:$G$186,$A7,RII_Data!$H$5:$H$186,"Direct",RII_Data!$C$5:$C$186,"Seed"),"") | F7: =IFERROR(AVERAGEIFS(RII_Data!$E$5:$E$186,RII_Data!$A$5:$A$186,F$4,RII_Data!$G$5:$G$186,$A7,RII_Data!$H$5:$H$186,"Direct",RII_Data!$C$5:$C$186,"Seed"),"") -> 0.8245 | G7: =IFERROR(AVERAGEIFS(RII_Data!$E$5:$E$186,RII_Data!$A$5:$A$186,G$4,RII_Data!$G$5:$G$186,$A7,RII_Data!$H$5:$H$186,"Direct",RII_Data!$C$5:$C$186,"Seed"),"") | H7: =COUNT(C7:G7) -> 3 | I7: =IF(H7=0,"",AVERAGE(C7:G7)) -> 0.76616667 | J7: =IF(I7="","",RANK(I7,$I$5:$I$42,0)+COUNTIFS($I$5:$I$42,I7,$A$5:$A$42,"<"&$A7)) -> 7 | K7: =IF(J7="","",5-INT((J7-1)*5/$C$44)) -> 4 | L7: =IF(K7="","not seeded","p"&K7&" × i"&K7) -> p4 × i4 | M7: =IF(K7="","",IF(K7^2<=5,"Low",IF(K7^2<=10,"Moderate",IF(K7^2<=15,"High","Extreme")))) -> Extreme
A8: R-SKILL | B8: Unskilled or unqualified labour | C8: =IFERROR(AVERAGEIFS(RII_Data!$E$5:$E$186,RII_Data!$A$5:$A$186,C$4,RII_Data!$G$5:$G$186,$A8,RII_Data!$H$5:$H$186,"Direct",RII_Data!$C$5:$C$186,"Seed"),"") -> 0.759 | D8: =IFERROR(AVERAGEIFS(RII_Data!$E$5:$E$186,RII_Data!$A$5:$A$186,D$4,RII_Data!$G$5:$G$186,$A8,RII_Data!$H$5:$H$186,"Direct",RII_Data!$C$5:$C$186,"Seed"),"") -> 0.787 | E8: =IFERROR(AVERAGEIFS(RII_Data!$E$5:$E$186,RII_Data!$A$5:$A$186,E$4,RII_Data!$G$5:$G$186,$A8,RII_Data!$H$5:$H$186,"Direct",RII_Data!$C$5:$C$186,"Seed"),"") | F8: =IFERROR(AVERAGEIFS(RII_Data!$E$5:$E$186,RII_Data!$A$5:$A$186,F$4,RII_Data!$G$5:$G$186,$A8,RII_Data!$H$5:$H$186,"Direct",RII_Data!$C$5:$C$186,"Seed"),"") | G8: =IFERROR(AVERAGEIFS(RII_Data!$E$5:$E$186,RII_Data!$A$5:$A$186,G$4,RII_Data!$G$5:$G$186,$A8,RII_Data!$H$5:$H$186,"Direct",RII_Data!$C$5:$C$186,"Seed"),"") -> 0.80333333 | H8: =COUNT(C8:G8) -> 3 | I8: =IF(H8=0,"",AVERAGE(C8:G8)) -> 0.78311111 | J8: =IF(I8="","",RANK(I8,$I$5:$I$42,0)+COUNTIFS($I$5:$I$42,I8,$A$5:$A$42,"<"&$A8)) -> 3 | K8: =IF(J8="","",5-INT((J8-1)*5/$C$44)) -> 5 | L8: =IF(K8="","not seeded","p"&K8&" × i"&K8) -> p5 × i5 | M8: =IF(K8="","",IF(K8^2<=5,"Low",IF(K8^2<=10,"Moderate",IF(K8^2<=15,"High","Extreme")))) -> Extreme
A9: R-PLAN | B9: Poor planning or unrealistic scheduling | C9: =IFERROR(AVERAGEIFS(RII_Data!$E$5:$E$186,RII_Data!$A$5:$A$186,C$4,RII_Data!$G$5:$G$186,$A9,RII_Data!$H$5:$H$186,"Direct",RII_Data!$C$5:$C$186,"Seed"),"") -> 0.791 | D9: =IFERROR(AVERAGEIFS(RII_Data!$E$5:$E$186,RII_Data!$A$5:$A$186,D$4,RII_Data!$G$5:$G$186,$A9,RII_Data!$H$5:$H$186,"Direct",RII_Data!$C$5:$C$186,"Seed"),"") | E9: =IFERROR(AVERAGEIFS(RII_Data!$E$5:$E$186,RII_Data!$A$5:$A$186,E$4,RII_Data!$G$5:$G$186,$A9,RII_Data!$H$5:$H$186,"Direct",RII_Data!$C$5:$C$186,"Seed"),"") -> 0.763184 | F9: =IFERROR(AVERAGEIFS(RII_Data!$E$5:$E$186,RII_Data!$A$5:$A$186,F$4,RII_Data!$G$5:$G$186,$A9,RII_Data!$H$5:$H$186,"Direct",RII_Data!$C$5:$C$186,"Seed"),"") | G9: =IFERROR(AVERAGEIFS(RII_Data!$E$5:$E$186,RII_Data!$A$5:$A$186,G$4,RII_Data!$G$5:$G$186,$A9,RII_Data!$H$5:$H$186,"Direct",RII_Data!$C$5:$C$186,"Seed"),"") | H9: =COUNT(C9:G9) -> 2 | I9: =IF(H9=0,"",AVERAGE(C9:G9)) -> 0.777092 | J9: =IF(I9="","",RANK(I9,$I$5:$I$42,0)+COUNTIFS($I$5:$I$42,I9,$A$5:$A$42,"<"&$A9)) -> 4 | K9: =IF(J9="","",5-INT((J9-1)*5/$C$44)) -> 5 | L9: =IF(K9="","not seeded","p"&K9&" × i"&K9) -> p5 × i5 | M9: =IF(K9="","",IF(K9^2<=5,"Low",IF(K9^2<=10,"Moderate",IF(K9^2<=15,"High","Extreme")))) -> Extreme
A10: R-SAFE | B10: Unsafe conditions or work at height | C10: =IFERROR(AVERAGEIFS(RII_Data!$E$5:$E$186,RII_Data!$A$5:$A$186,C$4,RII_Data!$G$5:$G$186,$A10,RII_Data!$H$5:$H$186,"Direct",RII_Data!$C$5:$C$186,"Seed"),"") -> 0.7865 | D10: =IFERROR(AVERAGEIFS(RII_Data!$E$5:$E$186,RII_Data!$A$5:$A$186,D$4,RII_Data!$G$5:$G$186,$A10,RII_Data!$H$5:$H$186,"Direct",RII_Data!$C$5:$C$186,"Seed"),"") | E10: =IFERROR(AVERAGEIFS(RII_Data!$E$5:$E$186,RII_Data!$A$5:$A$186,E$4,RII_Data!$G$5:$G$186,$A10,RII_Data!$H$5:$H$186,"Direct",RII_Data!$C$5:$C$186,"Seed"),"") | F10: =IFERROR(AVERAGEIFS(RII_Data!$E$5:$E$186,RII_Data!$A$5:$A$186,F$4,RII_Data!$G$5:$G$186,$A10,RII_Data!$H$5:$H$186,"Direct",RII_Data!$C$5:$C$186,"Seed"),"") | G10: =IFERROR(AVERAGEIFS(RII_Data!$E$5:$E$186,RII_Data!$A$5:$A$186,G$4,RII_Data!$G$5:$G$186,$A10,RII_Data!$H$5:$H$186,"Direct",RII_Data!$C$5:$C$186,"Seed"),"") | H10: =COUNT(C10:G10) -> 1 | I10: =IF(H10=0,"",AVERAGE(C10:G10)) -> 0.7865 | J10: =IF(I10="","",RANK(I10,$I$5:$I$42,0)+COUNTIFS($I$5:$I$42,I10,$A$5:$A$42,"<"&$A10)) -> 2 | K10: =IF(J10="","",5-INT((J10-1)*5/$C$44)) -> 5 | L10: =IF(K10="","not seeded","p"&K10&" × i"&K10) -> p5 × i5 | M10: =IF(K10="","",IF(K10^2<=5,"Low",IF(K10^2<=10,"Moderate",IF(K10^2<=15,"High","Extreme")))) -> Extreme
A11: R-WX | B11: Rain / monsoon stoppage | C11: =IFERROR(AVERAGEIFS(RII_Data!$E$5:$E$186,RII_Data!$A$5:$A$186,C$4,RII_Data!$G$5:$G$186,$A11,RII_Data!$H$5:$H$186,"Direct",RII_Data!$C$5:$C$186,"Seed"),"") -> 0.764 | D11: =IFERROR(AVERAGEIFS(RII_Data!$E$5:$E$186,RII_Data!$A$5:$A$186,D$4,RII_Data!$G$5:$G$186,$A11,RII_Data!$H$5:$H$186,"Direct",RII_Data!$C$5:$C$186,"Seed"),"") -> 0.7 | E11: =IFERROR(AVERAGEIFS(RII_Data!$E$5:$E$186,RII_Data!$A$5:$A$186,E$4,RII_Data!$G$5:$G$186,$A11,RII_Data!$H$5:$H$186,"Direct",RII_Data!$C$5:$C$186,"Seed"),"") -> 0.656716 | F11: =IFERROR(AVERAGEIFS(RII_Data!$E$5:$E$186,RII_Data!$A$5:$A$186,F$4,RII_Data!$G$5:$G$186,$A11,RII_Data!$H$5:$H$186,"Direct",RII_Data!$C$5:$C$186,"Seed"),"") -> 0.6528 | G11: =IFERROR(AVERAGEIFS(RII_Data!$E$5:$E$186,RII_Data!$A$5:$A$186,G$4,RII_Data!$G$5:$G$186,$A11,RII_Data!$H$5:$H$186,"Direct",RII_Data!$C$5:$C$186,"Seed"),"") | H11: =COUNT(C11:G11) -> 4 | I11: =IF(H11=0,"",AVERAGE(C11:G11)) -> 0.693379 | J11: =IF(I11="","",RANK(I11,$I$5:$I$42,0)+COUNTIFS($I$5:$I$42,I11,$A$5:$A$42,"<"&$A11)) -> 24 | K11: =IF(J11="","",5-INT((J11-1)*5/$C$44)) -> 2 | L11: =IF(K11="","not seeded","p"&K11&" × i"&K11) -> p2 × i2 | M11: =IF(K11="","",IF(K11^2<=5,"Low",IF(K11^2<=10,"Moderate",IF(K11^2<=15,"High","Extreme")))) -> Low
A12: R-RWK | B12: Rework due to workmanship or defects | C12: =IFERROR(AVERAGEIFS(RII_Data!$E$5:$E$186,RII_Data!$A$5:$A$186,C$4,RII_Data!$G$5:$G$186,$A12,RII_Data!$H$5:$H$186,"Direct",RII_Data!$C$5:$C$186,"Seed"),"") -> 0.736 | D12: =IFERROR(AVERAGEIFS(RII_Data!$E$5:$E$186,RII_Data!$A$5:$A$186,D$4,RII_Data!$G$5:$G$186,$A12,RII_Data!$H$5:$H$186,"Direct",RII_Data!$C$5:$C$186,"Seed"),"") | E12: =IFERROR(AVERAGEIFS(RII_Data!$E$5:$E$186,RII_Data!$A$5:$A$186,E$4,RII_Data!$G$5:$G$186,$A12,RII_Data!$H$5:$H$186,"Direct",RII_Data!$C$5:$C$186,"Seed"),"") -> 0.776119 | F12: =IFERROR(AVERAGEIFS(RII_Data!$E$5:$E$186,RII_Data!$A$5:$A$186,F$4,RII_Data!$G$5:$G$186,$A12,RII_Data!$H$5:$H$186,"Direct",RII_Data!$C$5:$C$186,"Seed"),"") | G12: =IFERROR(AVERAGEIFS(RII_Data!$E$5:$E$186,RII_Data!$A$5:$A$186,G$4,RII_Data!$G$5:$G$186,$A12,RII_Data!$H$5:$H$186,"Direct",RII_Data!$C$5:$C$186,"Seed"),"") | H12: =COUNT(C12:G12) -> 2 | I12: =IF(H12=0,"",AVERAGE(C12:G12)) -> 0.7560595 | J12: =IF(I12="","",RANK(I12,$I$5:$I$42,0)+COUNTIFS($I$5:$I$42,I12,$A$5:$A$42,"<"&$A12)) -> 11 | K12: =IF(J12="","",5-INT((J12-1)*5/$C$44)) -> 4 | L12: =IF(K12="","not seeded","p"&K12&" × i"&K12) -> p4 × i4 | M12: =IF(K12="","",IF(K12^2<=5,"Low",IF(K12^2<=10,"Moderate",IF(K12^2<=15,"High","Extreme")))) -> Extreme
A13: R-PAY | B13: Payment delay | C13: =IFERROR(AVERAGEIFS(RII_Data!$E$5:$E$186,RII_Data!$A$5:$A$186,C$4,RII_Data!$G$5:$G$186,$A13,RII_Data!$H$5:$H$186,"Direct",RII_Data!$C$5:$C$186,"Seed"),"") -> 0.773 | D13: =IFERROR(AVERAGEIFS(RII_Data!$E$5:$E$186,RII_Data!$A$5:$A$186,D$4,RII_Data!$G$5:$G$186,$A13,RII_Data!$H$5:$H$186,"Direct",RII_Data!$C$5:$C$186,"Seed"),"") -> 0.7758 | E13: =IFERROR(AVERAGEIFS(RII_Data!$E$5:$E$186,RII_Data!$A$5:$A$186,E$4,RII_Data!$G$5:$G$186,$A13,RII_Data!$H$5:$H$186,"Direct",RII_Data!$C$5:$C$186,"Seed"),"") -> 0.771144 | F13: =IFERROR(AVERAGEIFS(RII_Data!$E$5:$E$186,RII_Data!$A$5:$A$186,F$4,RII_Data!$G$5:$G$186,$A13,RII_Data!$H$5:$H$186,"Direct",RII_Data!$C$5:$C$186,"Seed"),"") | G13: =IFERROR(AVERAGEIFS(RII_Data!$E$5:$E$186,RII_Data!$A$5:$A$186,G$4,RII_Data!$G$5:$G$186,$A13,RII_Data!$H$5:$H$186,"Direct",RII_Data!$C$5:$C$186,"Seed"),"") | H13: =COUNT(C13:G13) -> 3 | I13: =IF(H13=0,"",AVERAGE(C13:G13)) -> 0.77331467 | J13: =IF(I13="","",RANK(I13,$I$5:$I$42,0)+COUNTIFS($I$5:$I$42,I13,$A$5:$A$42,"<"&$A13)) -> 5 | K13: =IF(J13="","",5-INT((J13-1)*5/$C$44)) -> 5 | L13: =IF(K13="","not seeded","p"&K13&" × i"&K13) -> p5 × i5 | M13: =IF(K13="","",IF(K13^2<=5,"Low",IF(K13^2<=10,"Moderate",IF(K13^2<=15,"High","Extreme")))) -> Extreme
A14: R-DES | B14: Design changes or incomplete documentation | C14: =IFERROR(AVERAGEIFS(RII_Data!$E$5:$E$186,RII_Data!$A$5:$A$186,C$4,RII_Data!$G$5:$G$186,$A14,RII_Data!$H$5:$H$186,"Direct",RII_Data!$C$5:$C$186,"Seed"),"") -> 0.732 | D14: =IFERROR(AVERAGEIFS(RII_Data!$E$5:$E$186,RII_Data!$A$5:$A$186,D$4,RII_Data!$G$5:$G$186,$A14,RII_Data!$H$5:$H$186,"Direct",RII_Data!$C$5:$C$186,"Seed"),"") | E14: =IFERROR(AVERAGEIFS(RII_Data!$E$5:$E$186,RII_Data!$A$5:$A$186,E$4,RII_Data!$G$5:$G$186,$A14,RII_Data!$H$5:$H$186,"Direct",RII_Data!$C$5:$C$186,"Seed"),"") -> 0.785075 | F14: =IFERROR(AVERAGEIFS(RII_Data!$E$5:$E$186,RII_Data!$A$5:$A$186,F$4,RII_Data!$G$5:$G$186,$A14,RII_Data!$H$5:$H$186,"Direct",RII_Data!$C$5:$C$186,"Seed"),"") | G14: =IFERROR(AVERAGEIFS(RII_Data!$E$5:$E$186,RII_Data!$A$5:$A$186,G$4,RII_Data!$G$5:$G$186,$A14,RII_Data!$H$5:$H$186,"Direct",RII_Data!$C$5:$C$186,"Seed"),"") | H14: =COUNT(C14:G14) -> 2 | I14: =IF(H14=0,"",AVERAGE(C14:G14)) -> 0.7585375 | J14: =IF(I14="","",RANK(I14,$I$5:$I$42,0)+COUNTIFS($I$5:$I$42,I14,$A$5:$A$42,"<"&$A14)) -> 10 | K14: =IF(J14="","",5-INT((J14-1)*5/$C$44)) -> 4 | L14: =IF(K14="","not seeded","p"&K14&" × i"&K14) -> p4 × i4 | M14: =IF(K14="","",IF(K14^2<=5,"Low",IF(K14^2<=10,"Moderate",IF(K14^2<=15,"High","Extreme")))) -> Extreme
A15: R-SUP | B15: Inadequate supervision or monitoring of workers | C15: =IFERROR(AVERAGEIFS(RII_Data!$E$5:$E$186,RII_Data!$A$5:$A$186,C$4,RII_Data!$G$5:$G$186,$A15,RII_Data!$H$5:$H$186,"Direct",RII_Data!$C$5:$C$186,"Seed"),"") -> 0.744 | D15: =IFERROR(AVERAGEIFS(RII_Data!$E$5:$E$186,RII_Data!$A$5:$A$186,D$4,RII_Data!$G$5:$G$186,$A15,RII_Data!$H$5:$H$186,"Direct",RII_Data!$C$5:$C$186,"Seed"),"") | E15: =IFERROR(AVERAGEIFS(RII_Data!$E$5:$E$186,RII_Data!$A$5:$A$186,E$4,RII_Data!$G$5:$G$186,$A15,RII_Data!$H$5:$H$186,"Direct",RII_Data!$C$5:$C$186,"Seed"),"") | F15: =IFERROR(AVERAGEIFS(RII_Data!$E$5:$E$186,RII_Data!$A$5:$A$186,F$4,RII_Data!$G$5:$G$186,$A15,RII_Data!$H$5:$H$186,"Direct",RII_Data!$C$5:$C$186,"Seed"),"") | G15: =IFERROR(AVERAGEIFS(RII_Data!$E$5:$E$186,RII_Data!$A$5:$A$186,G$4,RII_Data!$G$5:$G$186,$A15,RII_Data!$H$5:$H$186,"Direct",RII_Data!$C$5:$C$186,"Seed"),"") | H15: =COUNT(C15:G15) -> 1 | I15: =IF(H15=0,"",AVERAGE(C15:G15)) -> 0.744 | J15: =IF(I15="","",RANK(I15,$I$5:$I$42,0)+COUNTIFS($I$5:$I$42,I15,$A$5:$A$42,"<"&$A15)) -> 16 | K15: =IF(J15="","",5-INT((J15-1)*5/$C$44)) -> 3 | L15: =IF(K15="","not seeded","p"&K15&" × i"&K15) -> p3 × i3 | M15: =IF(K15="","",IF(K15^2<=5,"Low",IF(K15^2<=10,"Moderate",IF(K15^2<=15,"High","Extreme")))) -> Moderate
A16: R-MOT | B16: Low motivation, morale or labour turnover | C16: =IFERROR(AVERAGEIFS(RII_Data!$E$5:$E$186,RII_Data!$A$5:$A$186,C$4,RII_Data!$G$5:$G$186,$A16,RII_Data!$H$5:$H$186,"Direct",RII_Data!$C$5:$C$186,"Seed"),"") -> 0.736 | D16: =IFERROR(AVERAGEIFS(RII_Data!$E$5:$E$186,RII_Data!$A$5:$A$186,D$4,RII_Data!$G$5:$G$186,$A16,RII_Data!$H$5:$H$186,"Direct",RII_Data!$C$5:$C$186,"Seed"),"") | E16: =IFERROR(AVERAGEIFS(RII_Data!$E$5:$E$186,RII_Data!$A$5:$A$186,E$4,RII_Data!$G$5:$G$186,$A16,RII_Data!$H$5:$H$186,"Direct",RII_Data!$C$5:$C$186,"Seed"),"") | F16: =IFERROR(AVERAGEIFS(RII_Data!$E$5:$E$186,RII_Data!$A$5:$A$186,F$4,RII_Data!$G$5:$G$186,$A16,RII_Data!$H$5:$H$186,"Direct",RII_Data!$C$5:$C$186,"Seed"),"") | G16: =IFERROR(AVERAGEIFS(RII_Data!$E$5:$E$186,RII_Data!$A$5:$A$186,G$4,RII_Data!$G$5:$G$186,$A16,RII_Data!$H$5:$H$186,"Direct",RII_Data!$C$5:$C$186,"Seed"),"") | H16: =COUNT(C16:G16) -> 1 | I16: =IF(H16=0,"",AVERAGE(C16:G16)) -> 0.736 | J16: =IF(I16="","",RANK(I16,$I$5:$I$42,0)+COUNTIFS($I$5:$I$42,I16,$A$5:$A$42,"<"&$A16)) -> 17 | K16: =IF(J16="","",5-INT((J16-1)*5/$C$44)) -> 3 | L16: =IF(K16="","not seeded","p"&K16&" × i"&K16) -> p3 × i3 | M16: =IF(K16="","",IF(K16^2<=5,"Low",IF(K16^2<=10,"Moderate",IF(K16^2<=15,"High","Extreme")))) -> Moderate
... A42: R-FIN | B42: Contractor financial difficulties | C42: =IFERROR(AVERAGEIFS(RII_Data!$E$5:$E$186,RII_Data!$A$5:$A$186,C$4,RII_Data!$G$5:$G$186,$A42,RII_Data!$H$5:$H$186,"Direct",RII_Data!$C$5:$C$186,"Seed"),"") | D42: =IFERROR(AVERAGEIFS(RII_Data!$E$5:$E$186,RII_Data!$A$5:$A$186,D$4,RII_Data!$G$5:$G$186,$A42,RII_Data!$H$5:$H$186,"Direct",RII_Data!$C$5:$C$186,"Seed"),"") | E42: =IFERROR(AVERAGEIFS(RII_Data!$E$5:$E$186,RII_Data!$A$5:$A$186,E$4,RII_Data!$G$5:$G$186,$A42,RII_Data!$H$5:$H$186,"Direct",RII_Data!$C$5:$C$186,"Seed"),"") | F42: =IFERROR(AVERAGEIFS(RII_Data!$E$5:$E$186,RII_Data!$A$5:$A$186,F$4,RII_Data!$G$5:$G$186,$A42,RII_Data!$H$5:$H$186,"Direct",RII_Data!$C$5:$C$186,"Seed"),"") | G42: =IFERROR(AVERAGEIFS(RII_Data!$E$5:$E$186,RII_Data!$A$5:$A$186,G$4,RII_Data!$G$5:$G$186,$A42,RII_Data!$H$5:$H$186,"Direct",RII_Data!$C$5:$C$186,"Seed"),"") | H42: =COUNT(C42:G42) -> 0 | I42: =IF(H42=0,"",AVERAGE(C42:G42)) | J42: =IF(I42="","",RANK(I42,$I$5:$I$42,0)+COUNTIFS($I$5:$I$42,I42,$A$5:$A$42,"<"&$A42)) | K42: =IF(J42="","",5-INT((J42-1)*5/$C$44)) | L42: =IF(K42="","not seeded","p"&K42&" × i"&K42) -> not seeded | M42: =IF(K42="","",IF(K42^2<=5,"Low",IF(K42^2<=10,"Moderate",IF(K42^2<=15,"High","Extreme"))))
B44: Risks seeded (n) | C44: =COUNT(I5:I42) -> 30
B45: Highest mean RII | C45: =MAX(I5:I42) -> 0.78893333
B46: Lowest mean RII | C46: =MIN(I5:I42) -> 0.59403
B47: Spread (highest - lowest) | C47: =C45-C46 -> 0.19490333
B48: Spread without the lowest risk | C48: =C45-SMALL(I5:I42,2) -> 0.17893333
A51: How to read this sheet:
A52: 1. Study columns: AVERAGEIFS over RII_Data rows with that study, that risk, mapping = Direct and role = Seed. Two direct items in one study are averaged first, so every study counts once.
A53: 2. Seed mean RII = plain average of the study columns that have a value.
A54: 3. Rank 1 = highest mean. Class = 5 - INT((rank - 1) x 5 / n), n = number of seeded risks (cell below). The ranks are cut into five bands of about n/5 risks each; with n = 30, ranks 1-6 -> class 5, 7-12 -> 4, 13-18 -> 3, 19-24 -> 2, 25-30 -> 1. Risks with no seed-study value stay unranked.
A55: 4. The class is used for BOTH axes because an RII is an importance rating, not a probability and not days of delay. Level uses the app's thresholds: score <= 5 Low, <= 10 Moderate, <= 15 High, else Extreme.
A56: 5. In the app, a site-fact rule flag raises the probability class by one (max 5), and entering your own probability and delay replaces the seed completely.
A57: 6. Caution: most mean RIIs lie within a few hundredths of each other (see the spread rows). The bands make small differences look large, so treat the seed as a weak starting order.
A58: 7. Ties: equal means are ordered by risk ID, the same rule the app uses (R-MTH and R-STO tie at 0.700).

Sheet Validation
A1: Validation: does the seed ranking agree with studies the model did NOT use?
A2: Spearman rank correlation between the seed mean RII and each held-out study, over the risks both cover (direct items only).
A4: Study | B4: Region / respondents | C4: Risks in common (n) | D4: Spearman rho | E4: t | F4: p (two-tailed) | G4: Reading
A5: M10 | B5: Middle East (10 studies: Malaysia, Palestine, Kuwait, Qatar, Saudi Arabia, Egypt, Bahrain, Oman, Yemen, Vietnam); Meta-analysis: pooled RII ('effect summary', random model) of 35 factors | C5: =C33 -> 19 | D5: =C32 -> 0.28170253 | E5: =C34 -> 1.2105129 | F5: =C35 -> 0.24264424 | G5: =IF(F5<0.05,IF(D5>0,"Agrees (significant at 5%)","Disagrees (significant at 5%)"),IF(D5>=0.5,"Moderate agreement, not significant (small n)",IF(D5>=0.2,"Weak agreement, not significant",IF(D5<=-0.5,"Moderate disagreement, not significant (small n)",IF(D5<=-0.2,"Weak disagreement, not significant","No clear relation"))))) -> Weak agreement, not significant
A6: M15 | B6: Brazil (Brasilia); Private building companies; directors, managers, engineers | C6: =C52 -> 11 | D6: =C51 -> 0.62727273 | E6: =C53 -> 2.4163058 | F6: =C54 -> 0.038845254 | G6: =IF(F6<0.05,IF(D6>0,"Agrees (significant at 5%)","Disagrees (significant at 5%)"),IF(D6>=0.5,"Moderate agreement, not significant (small n)",IF(D6>=0.2,"Weak agreement, not significant",IF(D6<=-0.5,"Moderate disagreement, not significant (small n)",IF(D6<=-0.2,"Weak disagreement, not significant","No clear relation"))))) -> Agrees (significant at 5%)
A7: M14 | B7: Indonesia (East Java); Construction WORKERS' perspective | C7: =C73 -> 13 | D7: =C72 -> -0.18131868 | E7: =C74 -> -0.61150205 | F7: =C75 -> 0.55329501 | G7: =IF(F7<0.05,IF(D7>0,"Agrees (significant at 5%)","Disagrees (significant at 5%)"),IF(D7>=0.5,"Moderate agreement, not significant (small n)",IF(D7>=0.2,"Weak agreement, not significant",IF(D7<=-0.5,"Moderate disagreement, not significant (small n)",IF(D7<=-0.2,"Weak disagreement, not significant","No clear relation"))))) -> No clear relation
A11: M10: Adebowale & Agumba 2023 (Middle East (10 studies: Malaysia, Palestine, Kuwait, Qatar, Saudi Arabia, Egypt, Bahrain, Oman, Yemen, Vietnam))
A12: Risk ID | B12: Risk | C12: Seed mean RII | D12: Study RII (direct, averaged) | E12: Seed rank | F12: Study rank | G12: Rank difference
A13: R-MAT | B13: Brick / block / mortar material shortage or late delivery | C13: =INDEX(Seed_Calculation!$I$5:$I$42,MATCH(A13,Seed_Calculation!$A$5:$A$42,0)) -> 0.78893333 | D13: =AVERAGEIFS(RII_Data!$E$5:$E$186,RII_Data!$A$5:$A$186,"M10",RII_Data!$G$5:$G$186,A13,RII_Data!$H$5:$H$186,"Direct") -> 0.775 | E13: =RANK(C13,$C$13:$C$31,0)+(COUNTIF($C$13:$C$31,C13)-1)/2 -> 1 | F13: =RANK(D13,$D$13:$D$31,0)+(COUNTIF($D$13:$D$31,D13)-1)/2 -> 5 | G13: =E13-F13 -> -4
A14: R-TOOL | B14: Tools and equipment delay | C14: =INDEX(Seed_Calculation!$I$5:$I$42,MATCH(A14,Seed_Calculation!$A$5:$A$42,0)) -> 0.75275 | D14: =AVERAGEIFS(RII_Data!$E$5:$E$186,RII_Data!$A$5:$A$186,"M10",RII_Data!$G$5:$G$186,A14,RII_Data!$H$5:$H$186,"Direct") -> 0.691 | E14: =RANK(C14,$C$13:$C$31,0)+(COUNTIF($C$13:$C$31,C14)-1)/2 -> 8 | F14: =RANK(D14,$D$13:$D$31,0)+(COUNTIF($D$13:$D$31,D14)-1)/2 -> 14 | G14: =E14-F14 -> -6
A15: R-LAB | B15: Labour absenteeism or shortage | C15: =INDEX(Seed_Calculation!$I$5:$I$42,MATCH(A15,Seed_Calculation!$A$5:$A$42,0)) -> 0.76616667 | D15: =AVERAGEIFS(RII_Data!$E$5:$E$186,RII_Data!$A$5:$A$186,"M10",RII_Data!$G$5:$G$186,A15,RII_Data!$H$5:$H$186,"Direct") -> 0.66 | E15: =RANK(C15,$C$13:$C$31,0)+(COUNTIF($C$13:$C$31,C15)-1)/2 -> 5 | F15: =RANK(D15,$D$13:$D$31,0)+(COUNTIF($D$13:$D$31,D15)-1)/2 -> 18 | G15: =E15-F15 -> -13
A16: R-SKILL | B16: Unskilled or unqualified labour | C16: =INDEX(Seed_Calculation!$I$5:$I$42,MATCH(A16,Seed_Calculation!$A$5:$A$42,0)) -> 0.78311111 | D16: =AVERAGEIFS(RII_Data!$E$5:$E$186,RII_Data!$A$5:$A$186,"M10",RII_Data!$G$5:$G$186,A16,RII_Data!$H$5:$H$186,"Direct") -> 0.801 | E16: =RANK(C16,$C$13:$C$31,0)+(COUNTIF($C$13:$C$31,C16)-1)/2 -> 2 | F16: =RANK(D16,$D$13:$D$31,0)+(COUNTIF($D$13:$D$31,D16)-1)/2 -> 2 | G16: =E16-F16 -> 0
A17: R-PLAN | B17: Poor planning or unrealistic scheduling | C17: =INDEX(Seed_Calculation!$I$5:$I$42,MATCH(A17,Seed_Calculation!$A$5:$A$42,0)) -> 0.777092 | D17: =AVERAGEIFS(RII_Data!$E$5:$E$186,RII_Data!$A$5:$A$186,"M10",RII_Data!$G$5:$G$186,A17,RII_Data!$H$5:$H$186,"Direct") -> 0.698 | E17: =RANK(C17,$C$13:$C$31,0)+(COUNTIF($C$13:$C$31,C17)-1)/2 -> 3 | F17: =RANK(D17,$D$13:$D$31,0)+(COUNTIF($D$13:$D$31,D17)-1)/2 -> 12 | G17: =E17-F17 -> -9
A18: R-WX | B18: Rain / monsoon stoppage | C18: =INDEX(Seed_Calculation!$I$5:$I$42,MATCH(A18,Seed_Calculation!$A$5:$A$42,0)) -> 0.693379 | D18: =AVERAGEIFS(RII_Data!$E$5:$E$186,RII_Data!$A$5:$A$186,"M10",RII_Data!$G$5:$G$186,A18,RII_Data!$H$5:$H$186,"Direct") -> 0.715 | E18: =RANK(C18,$C$13:$C$31,0)+(COUNTIF($C$13:$C$31,C18)-1)/2 -> 16 | F18: =RANK(D18,$D$13:$D$31,0)+(COUNTIF($D$13:$D$31,D18)-1)/2 -> 10 | G18: =E18-F18 -> 6
A19: R-RWK | B19: Rework due to workmanship or defects | C19: =INDEX(Seed_Calculation!$I$5:$I$42,MATCH(A19,Seed_Calculation!$A$5:$A$42,0)) -> 0.7560595 | D19: =AVERAGEIFS(RII_Data!$E$5:$E$186,RII_Data!$A$5:$A$186,"M10",RII_Data!$G$5:$G$186,A19,RII_Data!$H$5:$H$186,"Direct") -> 0.761 | E19: =RANK(C19,$C$13:$C$31,0)+(COUNTIF($C$13:$C$31,C19)-1)/2 -> 7 | F19: =RANK(D19,$D$13:$D$31,0)+(COUNTIF($D$13:$D$31,D19)-1)/2 -> 6 | G19: =E19-F19 -> 1
A20: R-PAY | B20: Payment delay | C20: =INDEX(Seed_Calculation!$I$5:$I$42,MATCH(A20,Seed_Calculation!$A$5:$A$42,0)) -> 0.77331467 | D20: =AVERAGEIFS(RII_Data!$E$5:$E$186,RII_Data!$A$5:$A$186,"M10",RII_Data!$G$5:$G$186,A20,RII_Data!$H$5:$H$186,"Direct") -> 0.751 | E20: =RANK(C20,$C$13:$C$31,0)+(COUNTIF($C$13:$C$31,C20)-1)/2 -> 4 | F20: =RANK(D20,$D$13:$D$31,0)+(COUNTIF($D$13:$D$31,D20)-1)/2 -> 8 | G20: =E20-F20 -> -4
